Workbook

Sheet 담당자
B1: 현업팀 담당자
B2: Upated Date | C2: 260805
B4: 팀 명 | C4: 현업팀 담당자 | E4: 소재개발 AX팀 담당자 | F4: 1차 조사 자료 공유 및 보완 사항 공유 일자 | G4: 비고 | H4: Status ('260805) | I4: 검토 요청 사항
B5: 리사이클팀 | C5: 노태종 선임 | D5: 010-3858-7060 | E5: 박세호 님 | F5: TBD | H5: 미회신 | I5: (공통) Level 2,3,4는 모두 기입필요
B6: 양극재 1팀 | C6: 최재윤 사원 | D6: 010-2717-2841 | E6: 박세호 님 | F6: 7/29_09:00 ~ 09:30 | G6: 담당자 변경 ('26.07.30) | H6: 8/3 회신 (메일 회신) | I6: (공통) Level 2,3,4는 모두 기입필요 level 2,3 점검 (세분화 필요), 진구님 수정 버전 미반영
B7: 양극재 2팀 | C7: 오수연 선임 | D7: 010-7751-6959 | E7: 김진구 님 | F7: 7/29_미정 | H7: 8/3 회신 (팀즈 회신) | I7: (공통) Level 2,3,4는 모두 기입필요 H 열 ~ P 열 미 작성 (업데이트 필요)
B8: 양극재 3팀 | C8: 권승혁 책임 | D8: 010-5558-9852 | E8: 김진구 님 | F8: TBD | H8: 미회신 | I8: (공통) Level 2,3,4는 모두 기입필요
B9: 전구체 팀 | C9: 정해인 선임 | D9: 010-5656-7857 | E9: 임한민 님 | F9: 7/29_09:00 ~ 09:30 | H9: 8/5 회신 (메일 회신) | I9: (공통) Level 2,3,4는 모두 기입필요 현행 기준 Manhour(MH) 와 과제별 MH 수치가 상이함 기대 실험 수준 미작성 (U~W열) I열 ~ M열 미작성
B10: 양극재 선행팀 | C10: 신승순 선임 | D10: 010-8456-5611 | E10: 임한민 님 | F10: 7/29_09:00 ~ 09:30 | H10: 8/5 팀즈에 업로드 (임현민 님) | I10: (공통) Level 2,3,4는 모두 기입필요 현행 기준 MH와 각 과제별 MH 점검 (Q, 과제별 동일한 MH 이고 (Z~AS) 모두 합한 값이 현행 기준 MH(Q~T)인가?) 기대 실험 수준 미작성 (U~W열)
B11: 음극재 1팀 | C11: 신선영 책임 | D11: 010-7164-6404 | E11: 임가현 님 | F11: 7/29_09:30 ~ 10:00 | I11: (공통) Level 2,3,4는 모두 기입필요 과제별 MH 미작성 (양식 누락) (기존 양식의 Z ~ AS열)
B12: 음극재 2팀 | C12: 이수민 책임 | D12: 010-4377-5582 | E12: 임가현 님 | F12: 7/29_09:30 ~ 10:00 | I12: (공통) Level 2,3,4는 모두 기입필요 K열 ~ O열 정보 미흡 (추가 작성 필요) 과제별 MH 미작성 (양식 누락) (기존 양식의 Z ~ AS열)
B13: 전해질 1팀 | C13: 안성모 책임 | D13: 010-2365-6960 | E13: 안경호 님 | F13: 7/31_미정 | H13: 미회신 | I13: (공통) Level 2,3,4는 모두 기입필요
B14: 전해질 2팀 | C14: 문성진 선임 | D14: 010-4516-9882 | E14: 안경호 님 | F14: 7/31_미정 | H14: 미회신 | I14: (공통) Level 2,3,4는 모두 기입필요
B15: 분리막 1팀 | C15: 이용희 책임 | D15: 010-2017-4435 | E15: 방기력 님 | F15: 7/29_10:00 ~ 10:30 | H15: 미회신 | I15: (공통) Level 2,3,4는 모두 기입필요
B16: 분리막 2팀 | C16: 이지수 책임 | D16: 010-7499-5790 | E16: 방기력 님 | F16: 7/29_10:00 ~ 10:30 | H16: 미회신 | I16: (공통) Level 2,3,4는 모두 기입필요
B17: 파우치형부품팀 | C17: 김히나 책임 | D17: 010-3683-9089 | E17: 맹한솔 님 | F17: 8월 1주차 진행 | H17: 1차 작성 | I17: (공통) Level 2,3,4는 모두 기입필요 현업팀 점검 및 2차 작성요청 필요
B18: 요소소재팀 | C18: 미정 | D18: - | E18: 임현민 님 + α | F18: 8월 2주차 이후 진행 | G18: 담당자 지정 요청 / 신규 정의 필요 | H18: - | I18: (공통) Level 2,3,4는 모두 기입필요

Sheet Sheet6
E2: 100000 | F2: 100000 | H2: 100000000 | I2: 100000000
A3: 행 레이블 | B3: 합계 : Total [hrs] | C3: 합계 : 기대실험 Total [hrs] | H3: 현행 [억원] | I3: 기대실험 [억원] | N3: 현행 [억원] | O3: 기대실험 [억원]
A4: 리사이클 | B4: 5379.6 | C4: 7113.6 | E4: =B4*$E$2 -> 537960000 | F4: =C4*$F$2 -> 7.1136e+08 | H4: =E4/$I$2 -> 5.3796 | I4: =F4/$I$2 -> 7.1136 | M4: =A4 -> 리사이클 | N4: =H4 -> 5.3796 | O4: =I4 -> 7.1136 | P4: =O4/N4 -> 1.3223288
A5: 분리막 1팀 | B5: 15654.98 | C5: 112323.75 | E5: =B5*$E$2 -> 1.565498e+09 | F5: =C5*$F$2 -> 1.1232375e+10 | H5: =E5/$I$2 -> 15.65498 | I5: =F5/$I$2 -> 112.32375 | M5: =A5 -> 분리막 1팀 | N5: =H5 -> 15.65498 | O5: =I5 -> 112.32375 | P5: =O5/N5 -> 7.1749532 | Q5: =P5/2.4 -> 2.9895638 | S5: 185 | T5: 282 | U5: =T5/S5 -> 1.5243243
A6: 분리막 2팀 | B6: 29029.883 | C6: 81081.111 | E6: =B6*$E$2 -> 2.9029883e+09 | F6: =C6*$F$2 -> 8.1081111e+09 | H6: =E6/$I$2 -> 29.029883 | I6: =F6/$I$2 -> 81.081111 | M6: =A6 -> 분리막 2팀 | N6: =H6 -> 29.029883 | O6: =I6 -> 81.081111 | P6: =O6/N6 -> 2.7930223
A7: 양극재1팀 | B7: 9584.28 | C7: 19137.24 | E7: =B7*$E$2 -> 9.58428e+08 | F7: =C7*$F$2 -> 1.913724e+09 | H7: =E7/$I$2 -> 9.58428 | I7: =F7/$I$2 -> 19.13724 | M7: =A7 -> 양극재1팀 | N7: =H7 -> 9.58428 | O7: =I7 -> 19.13724 | P7: =O7/N7 -> 1.9967321
A8: 양극재2팀 | B8: 8500.8 | C8: 33528 | E8: =B8*$E$2 -> 8.5008e+08 | F8: =C8*$F$2 -> 3352800000 | H8: =E8/$I$2 -> 8.5008 | I8: =F8/$I$2 -> 33.528 | M8: =A8 -> 양극재2팀 | N8: =H8 -> 8.5008 | O8: =I8 -> 33.528 | P8: =O8/N8 -> 3.9440994
A9: 양극재3팀 | B9: 7941.84 | C9: 17417.76 | E9: =B9*$E$2 -> 7.94184e+08 | F9: =C9*$F$2 -> 1.741776e+09 | H9: =E9/$I$2 -> 7.94184 | I9: =F9/$I$2 -> 17.41776 | M9: =A9 -> 양극재3팀 | N9: =H9 -> 7.94184 | O9: =I9 -> 17.41776 | P9: =O9/N9 -> 2.1931643
A10: 양극재선행 | B10: 8365.32 | C10: 12547.98 | E10: =B10*$E$2 -> 8.36532e+08 | F10: =C10*$F$2 -> 1.254798e+09 | H10: =E10/$I$2 -> 8.36532 | I10: =F10/$I$2 -> 12.54798 | M10: =A10 -> 양극재선행 | N10: =H10 -> 8.36532 | O10: =I10 -> 12.54798 | P10: =O10/N10 -> 1.5
A11: 음극재 1팀 | B11: 5788.0176 | C11: 15566.749 | E11: =B11*$E$2 -> 5.7880176e+08 | F11: =C11*$F$2 -> 1.5566749e+09 | H11: =E11/$I$2 -> 5.7880176 | I11: =F11/$I$2 -> 15.566749 | M11: =A11 -> 음극재 1팀 | N11: =H11 -> 5.7880176 | O11: =I11 -> 15.566749 | P11: =O11/N11 -> 2.6894786
A12: 음극재 2팀 | B12: 11560.272 | C12: 15697.884 | E12: =B12*$E$2 -> 1156027200 | F12: =C12*$F$2 -> 1.5697884e+09 | H12: =E12/$I$2 -> 11.560272 | I12: =F12/$I$2 -> 15.697884 | M12: =A12 -> 음극재 2팀 | N12: =H12 -> 11.560272 | O12: =I12 -> 15.697884 | P12: =O12/N12 -> 1.3579165
A13: 전구체 | B13: 10396.8 | C13: 12487.68 | E13: =B13*$E$2 -> 1.03968e+09 | F13: =C13*$F$2 -> 1.248768e+09 | H13: =E13/$I$2 -> 10.3968 | I13: =F13/$I$2 -> 12.48768 | M13: =A13 -> 전구체 | N13: =H13 -> 10.3968 | O13: =I13 -> 12.48768 | P13: =O13/N13 -> 1.201108
A14: 전해질 1팀 | B14: 13540.08 | C14: 33398.4 | E14: =B14*$E$2 -> 1.354008e+09 | F14: =C14*$F$2 -> 3.33984e+09 | H14: =E14/$I$2 -> 13.54008 | I14: =F14/$I$2 -> 33.3984 | M14: =A14 -> 전해질 1팀 | N14: =H14 -> 13.54008 | O14: =I14 -> 33.3984 | P14: =O14/N14 -> 2.4666324
A15: 전해질 2팀 | B15: 15912.48 | C15: 28046.4 | E15: =B15*$E$2 -> 1591248000 | F15: =C15*$F$2 -> 2804640000 | H15: =E15/$I$2 -> 15.91248 | I15: =F15/$I$2 -> 28.0464 | M15: =A15 -> 전해질 2팀 | N15: =H15 -> 15.91248 | O15: =I15 -> 28.0464 | P15: =O15/N15 -> 1.7625411
A16: 총합계 | B16: 141654.35 | C16: 388346.55 | E16: =B16*$E$2 -> 1.4165435e+10 | F16: =C16*$F$2 -> 3.8834655e+10 | H16: =E16/$I$2 -> 141.65435 | I16: =F16/$I$2 -> 388.34655 | M16: =A16 -> 총합계 | N16: =H16 -> 141.65435 | O16: =I16 -> 388.34655 | P16: =O16/N16 -> 2.7415081
E17: =B17*$E$2 -> 0 | F17: =C17*$F$2 -> 0 | H17: =E17/$I$2 -> 0 | I17: =F17/$I$2 -> 0 | M17: =A17 -> 0 | N17: =H17 -> 0 | O17: =I17 -> 0 | P17: =O17/N17 -> #DIV/0!
E18: =B18*$E$2 -> 0 | F18: =C18*$F$2 -> 0 | H18: =E18/$I$2 -> 0 | I18: =F18/$I$2 -> 0 | M18: =A18 -> 0 | N18: =H18 -> 0 | O18: =I18 -> 0 | P18: =O18/N18 -> #DIV/0!
E19: =B19*$E$2 -> 0 | F19: =C19*$F$2 -> 0 | H19: =E19/$I$2 -> 0 | I19: =F19/$I$2 -> 0 | M19: =A19 -> 0 | N19: =H19 -> 0 | O19: =I19 -> 0 | P19: =O19/N19 -> #DIV/0!
E20: =B20*$E$2 -> 0 | F20: =C20*$F$2 -> 0 | H20: =E20/$I$2 -> 0 | I20: =F20/$I$2 -> 0 | M20: =A20 -> 0 | N20: =H20 -> 0 | O20: =I20 -> 0 | P20: =O20/N20 -> #DIV/0!
E21: =B21*$E$2 -> 0 | F21: =C21*$F$2 -> 0 | H21: =E21/$I$2 -> 0 | I21: =F21/$I$2 -> 0 | M21: =A21 -> 0 | N21: =H21 -> 0 | O21: =I21 -> 0 | P21: =O21/N21 -> #DIV/0!
E22: =B22*$E$2 -> 0 | F22: =C22*$F$2 -> 0 | H22: =E22/$I$2 -> 0 | I22: =F22/$I$2 -> 0 | M22: =A22 -> 0 | N22: =H22 -> 0 | O22: =I22 -> 0 | P22: =O22/N22 -> #DIV/0!
E23: =B23*$E$2 -> 0 | F23: =C23*$F$2 -> 0 | H23: =E23/$I$2 -> 0 | I23: =F23/$I$2 -> 0 | M23: =A23 -> 0 | N23: =H23 -> 0 | O23: =I23 -> 0 | P23: =O23/N23 -> #DIV/0!
E24: =B24*$E$2 -> 0 | F24: =C24*$F$2 -> 0 | H24: =E24/$I$2 -> 0 | I24: =F24/$I$2 -> 0 | M24: =A24 -> 0 | N24: =H24 -> 0 | O24: =I24 -> 0 | P24: =O24/N24 -> #DIV/0!
E25: =B25*$E$2 -> 0 | F25: =C25*$F$2 -> 0 | H25: =E25/$I$2 -> 0 | I25: =F25/$I$2 -> 0 | M25: =A25 -> 0 | N25: =H25 -> 0 | O25: =I25 -> 0 | P25: =O25/N25 -> #DIV/0!
E26: =B26*$E$2 -> 0 | F26: =C26*$F$2 -> 0 | H26: =E26/$I$2 -> 0 | I26: =F26/$I$2 -> 0 | M26: =A26 -> 0 | N26: =H26 -> 0 | O26: =I26 -> 0 | P26: =O26/N26 -> #DIV/0!
E27: =B27*$E$2 -> 0 | F27: =C27*$F$2 -> 0 | H27: =E27/$I$2 -> 0 | I27: =F27/$I$2 -> 0 | M27: =A27 -> 0 | N27: =H27 -> 0 | O27: =I27 -> 0 | P27: =O27/N27 -> #DIV/0!
E28: =B28*$E$2 -> 0 | F28: =C28*$F$2 -> 0 | H28: =E28/$I$2 -> 0 | I28: =F28/$I$2 -> 0 | M28: =A28 -> 0 | N28: =H28 -> 0 | O28: =I28 -> 0 | P28: =O28/N28 -> #DIV/0!
... E202: =B202*$E$2 -> 0 | F202: =C202*$F$2 -> 0 | H202: =E202/$I$2 -> 0 | I202: =F202/$I$2 -> 0 | M202: =A202 -> 0 | N202: =H202 -> 0 | O202: =I202 -> 0 | P202: =O202/N202 -> #DIV/0!

Sheet 소재개발 실험항목_Total_AX팀 관리
AD1: ※ 수행 과제별 M/M 산출 필요 시, 과제별 분류
F2: ↓ Level 2 분류 업데이트 후 Level 분류 쉬트에 내용 기입 | G2: ↓ 해당 실험의 목적을 기재 | H2: ↓ 각 실험 & 실험의 목적별 프로토콜 기입 | O2: ↓'260902_Data mapping 요청 | X2: ↓기대실험 횟수만 입력 | Y2: ↓자동 산출 (수정 x) | AD2: Manpower (현재 수행 실험 기준)
D3: LEVEL 0 | E3: LEVEL 1 | F3: LEVEL 2 | G3: LEVEL3 | H3: LEVEL4 | I3: LEVEL5 | K3: DOE | M3: 설비제어값 | N3: DATA List (for gathering) | P3: 각 단계별 의사 결정 시점 | R3: Manpower (현재 수행 실험 기준) | W3: Manpower (자동화 구현 시, 기대실험 기준 ) | Z3: 단위 실험 산출 기준 | AA3: 자동화 우선순위 | AD3: Manpower (핵심과제기준) | AI3: Manpower (주요과제기준) | AN3: Manpower (기반과제기준) | AS3: Manpower (시드과제기준)
B4: 분류 | C4: 팀명 | D4: 실험 분류 | E4: 공정 | F4: 실험/분석법 상세 | G4: 실험 목적 | H4: Process step or SOP | I4: 상세 설명 (필요시 기입) | J4: 주요 설비 | K4: x 값 List (실험인자, 영향인자, 변수) | L4: y 값 List (결과값 or 목표) | M4: 항목/SV | N4: Data (Input) 단위 실험에서 입력해야 하는 data 존재 시 기입 | O4: Data (취합 data list) ex, MDS data list 등 | P4: 유/무 (O/X) | Q4: 의사 결정자 (휴먼/기계) | R4: 수행 주체 (연구원/도급/외주) | S4: 수행 인원 [명/회] | T4: 소요 시간 [시간/회] | U4: 수행 빈도수 [회/월] | V4: Total [hrs] | W4: 소요 시간 [시간/회] | X4: 수행 빈도수 [회/월] | Y4: 기대실험 Total [hrs] | Z4: [variable/회] | AA4: O/X (x순위) | AB4: 비고 | AD4: 수행 주체 (연구원/도급/외주) | AE4: 수행 인원 [명/회] | AF4: 소요 시간 [시간/회] | AG4: 수행 빈도수 [회/월] | AH4: Total [hrs] | AI4: 수행 주체 (연구원/도급/외주) | AJ4: 수행 인원 [명/회] | AK4: 소요 시간 [시간/회] | AL4: 수행 빈도수 [회/월] | AM4: Total [hrs] | AN4: 수행 주체 (연구원/도급/외주) | AO4: 수행 인원 [명/회] | AP4: 소요 시간 [시간/회] | AQ4: 수행 빈도수 [회/월] | AR4: Total [hrs] | AS4: 수행 주체 (연구원/도급/외주) | AT4: 수행 인원 [명/회] | AU4: 소요 시간 [시간/회] | AV4: 수행 빈도수 [회/월] | AW4: Total [hrs]
A5: 1 | B5: 양극재기술 | C5: 양극재1팀 | D5: 분석/측정 실험 | E5: 활물질 분석 | F5: PSD 분석 | G5: 입도 분석 | H5: 샘플링 | I5: 장비 세팅 분산제 투입 (10방울) 및 measure background 클릭 | J5: Malvern mastersize, 스포이드, spatula | K5: 입자 크기 | L5: 분포량 | M5: 소재 type (NCM 2.2) 초음파 처리 조건 (1500rpm 70%) 입자 검출 범위 | N5: 소재 type | R5: 연구원 | S5: 1 | T5: 0.25 | U5: 100 | V5: =S5*T5*U5*12 -> 300 | W5: 0.25 | X5: 120 | Y5: =S5*T5*X5*12 -> 360 | Z5: 1소재, 3회 | AE5: 1 | AF5: 0.15 | AG5: 60 | AH5: =AE5*AF5*AG5*12 -> 108 | AJ5: 1 | AK5: 0.15 | AL5: 60 | AM5: =AJ5*AK5*AL5*12 -> 108 | AO5: 1 | AP5: 0.15 | AQ5: 60 | AR5: =AO5*AP5*AQ5*12 -> 108 | AT5: 1 | AU5: 0.15 | AV5: 60 | AW5: =AT5*AU5*AV5*12 -> 108
A6: 2 | B6: 양극재기술 | C6: 양극재1팀 | D6: 분석/측정 실험 | E6: 활물질 분석 | F6: PSD 분석 | G6: 입도 분석 | H6: 외부 초음파 | I6: 파우더 전처리 파우더 투입 후 초음파 처리 (소듐 양극재의 경우 파우더와 분산제 미리 혼합하여 선분산액 제조 필요) | R6: 연구원 | Y6: =S6*T6*X6*12 -> 0 | AE6: 1 | AF6: 0.3 | AG6: 4 | AH6: =AE6*AF6*AG6*12 -> 14.4 | AJ6: 1 | AK6: 0.3 | AL6: 4 | AM6: =AJ6*AK6*AL6*12 -> 14.4 | AO6: 1 | AP6: 0.3 | AQ6: 4 | AR6: =AO6*AP6*AQ6*12 -> 14.4 | AT6: 1 | AU6: 0.3 | AV6: 4 | AW6: =AT6*AU6*AV6*12 -> 14.4
A7: 3 | B7: 양극재기술 | C7: 양극재1팀 | D7: 분석/측정 실험 | E7: 활물질 분석 | F7: PSD 분석 | G7: 입도 분석 | H7: 입도 측정 | I7: 측정 (3회) | R7: 연구원 | Y7: =S7*T7*X7*12 -> 0 | AH7: =AE7*AF7*AG7*12 -> 0 | AM7: =AJ7*AK7*AL7*12 -> 0 | AR7: =AO7*AP7*AQ7*12 -> 0 | AW7: =AT7*AU7*AV7*12 -> 0
A8: 4 | B8: 양극재기술 | C8: 양극재1팀 | D8: 분석/측정 실험 | E8: 활물질 분석 | F8: PSD 분석 | G8: 입도 분석 | H8: 장비 세척 | I8: 측정 장비를 세척한다. | R8: 연구원 | Y8: =S8*T8*X8*12 -> 0 | AH8: =AE8*AF8*AG8*12 -> 0 | AM8: =AJ8*AK8*AL8*12 -> 0 | AR8: =AO8*AP8*AQ8*12 -> 0 | AW8: =AT8*AU8*AV8*12 -> 0
A9: 5 | B9: 양극재기술 | C9: 양극재1팀 | D9: 분석/측정 실험 | E9: 활물질 분석 | F9: PSD 분석 | G9: 입도 분석 | H9: Data 정리 | I9: Data 추출 (vol. /Num. 기준 각각) 및 정리/그래프 그리기, (측정 및 클리닝에 사용되는 폐수 주기적으로 별도 폐기 필요) | O9: 실험일자, 실험장비, 실험조건, dmin, d10, d50, d90, dmax, Span, 1um 이하 미분 (Vol. Num. 기준 각각) 5회 측정 값 및 평균값 각각 도출 전체 입도 분포 그래프 | R9: 연구원 | S9: 1 | T9: 0.3 | U9: 36 | V9: =S9*T9*U9*12 -> 129.6 | W9: 0.3 | X9: 50 | Y9: =S9*T9*X9*12 -> 180 | Z9: 1소재, 1회 | AB9: 평균 이용 | AH9: =AE9*AF9*AG9*12 -> 0 | AM9: =AJ9*AK9*AL9*12 -> 0 | AR9: =AO9*AP9*AQ9*12 -> 0 | AW9: =AT9*AU9*AV9*12 -> 0
A10: 6 | B10: 양극재기술 | C10: 양극재1팀 | D10: 분석/측정 실험 | E10: 활물질 분석 | F10: BET 측정 | G10: 입도 분석 | H10: 업체 데이터 사용중 | I10: 업체 데이터 사용중 | O10: 비표면적, 기공구조 | R10: 외주 | S10: 0 | T10: 0 | U10: 0 | V10: =S10*T10*U10*12 -> 0 | W10: 0 | X10: 0 | Y10: =S10*T10*X10*12 -> 0 | AB10: 업체에서 측정한 데이터 사용 | AE10: 1 | AF10: 0.25 | AG10: 60 | AH10: =AE10*AF10*AG10*12 -> 180 | AJ10: 1 | AK10: 0.25 | AL10: 60 | AM10: =AJ10*AK10*AL10*12 -> 180 | AO10: 1 | AP10: 0.25 | AQ10: 60 | AR10: =AO10*AP10*AQ10*12 -> 180 | AT10: 1 | AU10: 0.25 | AV10: 60 | AW10: =AT10*AU10*AV10*12 -> 180
A11: 7 | B11: 양극재기술 | C11: 양극재1팀 | D11: 분석/측정 실험 | E11: 활물질 분석 | F11: Tap 밀도 분석 (수직식) | G11: Tap 밀도 분석 | H11: 업체 데이터 사용중 | I11: 업체 데이터 사용중 | R11: 외주 | S11: 0 | T11: 0 | U11: 0 | V11: =S11*T11*U11*12 -> 0 | W11: 0 | X11: 0 | Y11: =S11*T11*X11*12 -> 0 | AB11: 업체에서 측정한 데이터 사용 | AH11: =AE11*AF11*AG11*12 -> 0 | AM11: =AJ11*AK11*AL11*12 -> 0 | AR11: =AO11*AP11*AQ11*12 -> 0 | AW11: =AT11*AU11*AV11*12 -> 0
A12: 8 | B12: 양극재기술 | C12: 양극재1팀 | D12: 분석/측정 실험 | E12: 활물질 분석 | F12: Pellet density 분석 | G12: 압연밀도 (이차입자: 2ton, 단결정: 9ton) 측정 | H12: 장비 세팅 | I12: 장비세팅 장비에 빈 몰드 로딩 뒤 원점 측정. (같은 몰드 사용한 연속측정 시 본 step 생략) | J12: 2ton PD: 분체저항측정기 (HPRM-AM2) 9ton PD: Hantech Auto Lab Press | K12: 압력 | L12: pallet 밀도 혹은 두께 | M12: 유지시간 3s 초기 시료 무게 3g 원점 (22.2~22.4) | N12: 시료 초기 무게, 설정 압력 | R12: 연구원 | S12: 1 | T12: 0.25 | U12: 100 | V12: =S12*T12*U12*12 -> 300 | W12: 0.25 | X12: 120 | Y12: =S12*T12*X12*12 -> 360 | Z12: 1소재, 1회 | AE12: 1 | AF12: 0.15 | AG12: 60 | AH12: =AE12*AF12*AG12*12 -> 108 | AJ12: 1 | AK12: 0.15 | AL12: 60 | AM12: =AJ12*AK12*AL12*12 -> 108 | AO12: 1 | AP12: 0.15 | AQ12: 60 | AR12: =AO12*AP12*AQ12*12 -> 108 | AT12: 1 | AU12: 0.15 | AV12: 60 | AW12: =AT12*AU12*AV12*12 -> 108
A13: 9 | B13: 양극재기술 | C13: 양극재1팀 | D13: 분석/측정 실험 | E13: 활물질 분석 | F13: Pellet density 분석 | G13: 압연밀도 (이차입자: 2ton, 단결정: 9ton) 측정 | H13: 무게 측정 | I13: 계량 몰드 회수 후 파우더 계량 (2ton: 5.0g, 9ton: 3.0g) | R13: 연구원 | Y13: =S13*T13*X13*12 -> 0 | AE13: 1 | AF13: 0.1 | AG13: 60 | AH13: =AE13*AF13*AG13*12 -> 72 | AJ13: 1 | AK13: 0.1 | AL13: 60 | AM13: =AJ13*AK13*AL13*12 -> 72 | AO13: 1 | AP13: 0.1 | AQ13: 60 | AR13: =AO13*AP13*AQ13*12 -> 72 | AT13: 1 | AU13: 0.1 | AV13: 60 | AW13: =AT13*AU13*AV13*12 -> 72
A14: 10 | B14: 양극재기술 | C14: 양극재1팀 | D14: 분석/측정 실험 | E14: 활물질 분석 | F14: Pellet density 분석 | G14: 압연밀도 (이차입자: 2ton, 단결정: 9ton) 측정 | H14: 샘플링 | I14: 몰드 뚜껑 부분 열고 파우더 투입. 파우더 넘침 방지 위해 테이블을 몰드 바닥면으로 쳐서 다지기 (절반 정도 넣고 시행, 총 2회) | R14: 연구원 | Y14: =S14*T14*X14*12 -> 0 | AE14: 1 | AF14: 0.1 | AG14: 60 | AH14: =AE14*AF14*AG14*12 -> 72 | AJ14: 1 | AK14: 0.1 | AL14: 60 | AM14: =AJ14*AK14*AL14*12 -> 72 | AO14: 1 | AP14: 0.1 | AQ14: 60 | AR14: =AO14*AP14*AQ14*12 -> 72 | AT14: 1 | AU14: 0.1 | AV14: 60 | AW14: =AT14*AU14*AV14*12 -> 72
A15: 11 | B15: 양극재기술 | C15: 양극재1팀 | D15: 분석/측정 실험 | E15: 활물질 분석 | F15: Pellet density 분석 | G15: 압연밀도 (이차입자: 2ton, 단결정: 9ton) 측정 | H15: 몰드 조립 | I15: 몰드 조립 몰드 천천히 닫기 (좌, 우로 돌려가며 몰드 내 trap된 공기 빼주면서 시행 | R15: 연구원 | Y15: =S15*T15*X15*12 -> 0 | AE15: 1 | AF15: 0.1 | AG15: 4 | AH15: =AE15*AF15*AG15*12 -> 4.8 | AJ15: 1 | AK15: 0.1 | AL15: 4 | AM15: =AJ15*AK15*AL15*12 -> 4.8 | AO15: 1 | AP15: 0.1 | AQ15: 4 | AR15: =AO15*AP15*AQ15*12 -> 4.8 | AT15: 1 | AU15: 0.1 | AV15: 4 | AW15: =AT15*AU15*AV15*12 -> 4.8
A16: 12 | B16: 양극재기술 | C16: 양극재1팀 | D16: 분석/측정 실험 | E16: 활물질 분석 | F16: Pellet density 분석 | G16: 압연밀도 (이차입자: 2ton, 단결정: 9ton) 측정 | H16: 몰드 결착 | I16: 측정장비에 몰드 결착 장비에 몰드 탑재 | R16: 연구원 | Y16: =S16*T16*X16*12 -> 0 | AE16: 1 | AF16: 2 | AG16: 4 | AH16: =AE16*AF16*AG16*12 -> 96 | AJ16: 1 | AK16: 2 | AL16: 4 | AM16: =AJ16*AK16*AL16*12 -> 96 | AO16: 1 | AP16: 2 | AQ16: 4 | AR16: =AO16*AP16*AQ16*12 -> 96 | AT16: 1 | AU16: 2 | AV16: 4 | AW16: =AT16*AU16*AV16*12 -> 96
A17: 13 | B17: 양극재기술 | C17: 양극재1팀 | D17: 분석/측정 실험 | E17: 활물질 분석 | F17: Pellet density 분석 | G17: 압연밀도 (이차입자: 2ton, 단결정: 9ton) 측정 | H17: PD측정 | I17: 측정 시작 측정 및 압연밀도 기록 | R17: 연구원 | Y17: =S17*T17*X17*12 -> 0 | AE17: 1 | AF17: 0.3 | AG17: 4 | AH17: =AE17*AF17*AG17*12 -> 14.4 | AJ17: 1 | AK17: 0.3 | AL17: 4 | AM17: =AJ17*AK17*AL17*12 -> 14.4 | AO17: 1 | AP17: 0.3 | AQ17: 4 | AR17: =AO17*AP17*AQ17*12 -> 14.4 | AT17: 1 | AU17: 0.3 | AV17: 4 | AW17: =AT17*AU17*AV17*12 -> 14.4
A18: 14 | B18: 양극재기술 | C18: 양극재1팀 | D18: 분석/측정 실험 | E18: 활물질 분석 | F18: Pellet density 분석 | G18: 압연밀도 (이차입자: 2ton, 단결정: 9ton) 측정 | H18: 장비 세척 | I18: 세정 파우더 폐기 및 몰드 세척 (물, 아세톤), 건조 | R18: 연구원 | Y18: =S18*T18*X18*12 -> 0 | AE18: 1 | AF18: 0.1 | AG18: 4 | AH18: =AE18*AF18*AG18*12 -> 4.8 | AJ18: 1 | AK18: 0.1 | AL18: 4 | AM18: =AJ18*AK18*AL18*12 -> 4.8 | AO18: 1 | AP18: 0.1 | AQ18: 4 | AR18: =AO18*AP18*AQ18*12 -> 4.8 | AT18: 1 | AU18: 0.1 | AV18: 4 | AW18: =AT18*AU18*AV18*12 -> 4.8
A19: 15 | B19: 양극재기술 | C19: 양극재1팀 | D19: 분석/측정 실험 | E19: 활물질 분석 | F19: Pellet density 분석 | G19: 압연밀도 (이차입자: 2ton, 단결정: 9ton) 측정 | H19: Data 정리 | I19: Data 추출 및 정리 | O19: 펠렛 두께, 펠렛 밀도 (2ton, 9ton), 활물질 무게 | R19: 연구원 | S19: 1 | T19: 0.2 | U19: 4 | V19: =S19*T19*U19*12 -> 9.6 | W19: 0.05 | X19: 5 | Y19: =S19*T19*X19*12 -> 12 | AE19: 1 | AF19: 0.1 | AG19: 4 | AH19: =AE19*AF19*AG19*12 -> 4.8 | AJ19: 1 | AK19: 0.1 | AL19: 4 | AM19: =AJ19*AK19*AL19*12 -> 4.8 | AO19: 1 | AP19: 0.1 | AQ19: 4 | AR19: =AO19*AP19*AQ19*12 -> 4.8 | AT19: 1 | AU19: 0.1 | AV19: 4 | AW19: =AT19*AU19*AV19*12 -> 4.8
A20: 16 | B20: 양극재기술 | C20: 양극재1팀 | D20: 분석/측정 실험 | E20: 활물질 분석 | F20: ICP 분석_x000D_ | G20: 특정 원소 함량 분석 | H20: 분석 담당 의뢰중 | O20: 메인원소, 도핑원소, 코팅원소 | R20: 외주 | S20: 0 | T20: 0 | U20: 0 | V20: =S20*T20*U20*12 -> 0 | W20: 0 | X20: 0 | Y20: =S20*T20*X20*12 -> 0 | AB20: 무기분석팀 의뢰 | AE20: 1 | AF20: 0.05 | AG20: 4 | AH20: =AE20*AF20*AG20*12 -> 2.4 | AJ20: 1 | AK20: 0.05 | AL20: 4 | AM20: =AJ20*AK20*AL20*12 -> 2.4 | AO20: 1 | AP20: 0.05 | AQ20: 4 | AR20: =AO20*AP20*AQ20*12 -> 2.4 | AT20: 1 | AU20: 0.05 | AV20: 4 | AW20: =AT20*AU20*AV20*12 -> 2.4
A21: 17 | B21: 양극재기술 | C21: 양극재1팀 | D21: 분석/측정 실험 | E21: 활물질 분석 | F21: XRD 분석 | G21: 결정구조/상(phase) 분석 | H21: 샘플링 | I21: 드라이룸에서 시료 소분 후 분석실 이동 --> 샘플 홀더에 powder 평평하게 샘플링 (한 소재당 1개의 시료/1회 측정), 홀더 주변 클리닝 (에틸알콜 등), 홀더에 샘플명/이름/날짜 수기로 기입, 샘플 홀더 장비에 투입 후 측정 패턴 및 저장 setting | J21: 샘플 홀더, XRD (분석 담당 내 오픈 장비 사용 중 : Bruker사 D8 Endeavor 사용 중) | K21: 2 theta | L21: peak intensity | N21: scan 조건 (각도 범위) step size, step 당 머무르는 시간, 전압, 전류 | O21: scan 한 풀 패턴 데이터 리트벨트 분석을 통한 cell parameter, c/a ratio, 부피, 밀도, strain, cation mixing, 결정 크기, 불순물 여부 등 | R21: 연구원 | S21: 1 | T21: 0.15 | U21: 60 | V21: =S21*T21*U21*12 -> 108 | W21: 0.15 | X21: 100 | Y21: =S21*T21*X21*12 -> 180 | Z21: 1소재, 1회 | AH21: =AE21*AF21*AG21*12 -> 0 | AM21: =AJ21*AK21*AL21*12 -> 0 | AR21: =AO21*AP21*AQ21*12 -> 0 | AW21: =AT21*AU21*AV21*12 -> 0
A22: 18 | B22: 양극재기술 | C22: 양극재1팀 | D22: 분석/측정 실험 | E22: 활물질 분석 | F22: XRD 분석 | G22: 결정구조/상(phase) 분석 | H22: XRD 측정 | I22: XRD 측정 | J22: XRD (분석 담당 내 오픈 장비 사용 중 : Bruker사 D8 Endeavor 사용 중) | R22: 연구원 | V22: =S22*T22*U22*12 -> 0 | Y22: =S22*T22*X22*12 -> 0 | AE22: 2 | AF22: 0.33 | AG22: 150 | AH22: =AE22*AF22*AG22*12 -> 1188 | AJ22: 2 | AK22: 0.33 | AL22: 150 | AM22: =AJ22*AK22*AL22*12 -> 1188 | AO22: 2 | AP22: 0.33 | AQ22: 150 | AR22: =AO22*AP22*AQ22*12 -> 1188 | AT22: 2 | AU22: 0.33 | AV22: 150 | AW22: =AT22*AU22*AV22*12 -> 1188
A23: 19 | B23: 양극재기술 | C23: 양극재1팀 | D23: 분석/측정 실험 | E23: 활물질 분석 | F23: XRD 분석 | G23: 결정구조/상(phase) 분석 | H23: Data 변환 및 fitting | I23: 분석실 이동 + XRD 측정 컴퓨터에 있는 Eva/ topas 프로그램을 이용하여 data 변환 및 추출 | R23: 연구원 | S23: 1 | T23: 0.1 | U23: 60 | V23: =S23*T23*U23*12 -> 72 | W23: 0.1 | X23: 100 | Y23: =S23*T23*X23*12 -> 120 | AE23: 1 | AF23: 0.1 | AG23: 150 | AH23: =AE23*AF23*AG23*12 -> 180 | AJ23: 1 | AK23: 0.1 | AL23: 150 | AM23: =AJ23*AK23*AL23*12 -> 180 | AO23: 1 | AP23: 0.1 | AQ23: 150 | AR23: =AO23*AP23*AQ23*12 -> 180 | AT23: 1 | AU23: 0.1 | AV23: 150 | AW23: =AT23*AU23*AV23*12 -> 180
A24: 20 | B24: 양극재기술 | C24: 양극재1팀 | D24: 분석/측정 실험 | E24: 활물질 분석 | F24: XRD 분석 | G24: 결정구조/상(phase) 분석 | H24: 세척 및 정리 | I24: 사용한 샘플홀더 세척 및 정리 | R24: 연구원 | S24: 1 | T24: 0.1 | U24: 60 | V24: =S24*T24*U24*12 -> 72 | W24: 0.1 | X24: 100 | Y24: =S24*T24*X24*12 -> 120 | AE24: 0 | AF24: 0.33 | AG24: 150 | AH24: =AE24*AF24*AG24*12 -> 0 | AJ24: 0 | AK24: 0.33 | AL24: 150 | AM24: =AJ24*AK24*AL24*12 -> 0 | AO24: 0 | AP24: 0.33 | AQ24: 150 | AR24: =AO24*AP24*AQ24*12 -> 0 | AT24: 0 | AU24: 0.33 | AV24: 150 | AW24: =AT24*AU24*AV24*12 -> 0
A25: 21 | B25: 양극재기술 | C25: 양극재1팀 | D25: 분석/측정 실험 | E25: 활물질 분석 | F25: XRD 분석 | G25: 결정구조/상(phase) 분석 | H25: 그래프 생성 | I25: 추출한 data로 그래프 생성 | R25: 연구원 | S25: 1 | T25: 0.1 | U25: 60 | V25: =S25*T25*U25*12 -> 72 | W25: 0.1 | X25: 100 | Y25: =S25*T25*X25*12 -> 120 | AE25: 2 | AF25: 0.33 | AG25: 150 | AH25: =AE25*AF25*AG25*12 -> 1188 | AJ25: 2 | AK25: 0.33 | AL25: 150 | AM25: =AJ25*AK25*AL25*12 -> 1188 | AO25: 2 | AP25: 0.33 | AQ25: 150 | AR25: =AO25*AP25*AQ25*12 -> 1188 | AT25: 2 | AU25: 0.33 | AV25: 150 | AW25: =AT25*AU25*AV25*12 -> 1188
A26: 22 | B26: 양극재기술 | C26: 양극재1팀 | D26: 분석/측정 실험 | E26: 활물질 분석 | F26: SEM 분석_x000D_ | G26: 소재 이미지 분석 | H26: 샘플링 | I26: 샘플홀더에 카본테이브 부착 후, 소량의 powder (혹은 전극) 부착 | J26: SEM 홀더, 카본테이프 | M26: 작동거리 (WD) 10 정도 가속전압 5kV | R26: 연구원 | S26: 1 | T26: 0.05 | U26: 60 | V26: =S26*T26*U26*12 -> 36 | W26: 0.05 | X26: 100 | Y26: =S26*T26*X26*12 -> 60 | Z26: 1소재, 1회 | AH26: =AE26*AF26*AG26*12 -> 0 | AM26: =AJ26*AK26*AL26*12 -> 0 | AR26: =AO26*AP26*AQ26*12 -> 0 | AW26: =AT26*AU26*AV26*12 -> 0
A27: 23 | B27: 양극재기술 | C27: 양극재1팀 | D27: 분석/측정 실험 | E27: 활물질 분석 | F27: SEM 분석_x000D_ | G27: 소재 이미지 분석 | H27: 샘플 홀더 장비로 투입 | I27: 분석실로 이동+샘플 홀더 장비로 투입 | R27: 연구원 | S27: 1 | T27: 0.05 | U27: 10 | V27: =S27*T27*U27*12 -> 6 | W27: 0.05 | X27: 16 | Y27: =S27*T27*X27*12 -> 9.6 | AH27: =AE27*AF27*AG27*12 -> 0 | AM27: =AJ27*AK27*AL27*12 -> 0 | AR27: =AO27*AP27*AQ27*12 -> 0 | AW27: =AT27*AU27*AV27*12 -> 0
A28: 24 | B28: 양극재기술 | C28: 양극재1팀 | D28: 분석/측정 실험 | E28: 활물질 분석 | F28: SEM 분석_x000D_ | G28: 소재 이미지 분석 | H28: 이미지 생성 | I28: 원하는 샘플 SEM 이미지 (입자의 형태를 잘 확인할 수 있는) 확인 후 배율별로 각각 캡쳐 (배율별, SE/BSE 모드 각각 촬영) | J28: SEM (분석 담당 내 오픈 장비 사용 중 : Hitachi사 S4800 또는 JEOL IT710HR 등) | O28: 실험일자, 실험장비, (x1k, x2k, x5k, x10k, 20k, 30k) 이미지, 단면이미지 | R28: 연구원 | S28: 1 | T28: 2 | U28: 10 | V28: =S28*T28*U28*12 -> 240 | W28: 2 | X28: 16 | Y28: =S28*T28*X28*12 -> 384 | AE28: 1 | AF28: 0.33 | AG28: 4 | AH28: =AE28*AF28*AG28*12 -> 15.84 | AJ28: 1 | AK28: 0.33 | AL28: 4 | AM28: =AJ28*AK28*AL28*12 -> 15.84 | AO28: 1 | AP28: 0.33 | AQ28: 4 | AR28: =AO28*AP28*AQ28*12 -> 15.84 | AT28: 1 | AU28: 0.33 | AV28: 4 | AW28: =AT28*AU28*AV28*12 -> 15.84
A29: 25 | B29: 양극재기술 | C29: 양극재1팀 | D29: 분석/측정 실험 | E29: 활물질 분석 | F29: SEM 분석_x000D_ | G29: 소재 이미지 분석 | H29: EDS 분석_x000D_ | I29: EDS 분석 | J29: SEM (분석 담당 내 오픈 장비 사용 중 : Hitachi사 S4800 또는 JEOL IT710HR 등) | M29: 가속전압 15kV | O29: 구성 원소 정성, 정량 분석 / 원소 분포 | R29: 연구원 | S29: 1 | T29: 0.3 | U29: 30 | V29: =S29*T29*U29*12 -> 108 | W29: 0.3 | X29: 50 | Y29: =S29*T29*X29*12 -> 180 | AB29: MDS에 없음 | AE29: 1 | AF29: 0.1 | AG29: 4 | AH29: =AE29*AF29*AG29*12 -> 4.8 | AJ29: 1 | AK29: 0.1 | AL29: 4 | AM29: =AJ29*AK29*AL29*12 -> 4.8 | AO29: 1 | AP29: 0.1 | AQ29: 4 | AR29: =AO29*AP29*AQ29*12 -> 4.8 | AT29: 1 | AU29: 0.1 | AV29: 4 | AW29: =AT29*AU29*AV29*12 -> 4.8
A30: 26 | B30: 양극재기술 | C30: 양극재1팀 | D30: 분석/측정 실험 | E30: 활물질 분석 | F30: SEM 분석_x000D_ | G30: 소재 이미지 분석 | H30: Data 저장_x000D_ | I30: Data 저장 후 추출 | R30: 연구원 | S30: 1 | T30: 0.1 | U30: 10 | V30: =S30*T30*U30*12 -> 12 | W30: 0.05 | X30: 20 | Y30: =S30*T30*X30*12 -> 24 | AE30: 1 | AF30: 0.2 | AG30: 150 | AH30: =AE30*AF30*AG30*12 -> 360 | AJ30: 1 | AK30: 0.2 | AL30: 150 | AM30: =AJ30*AK30*AL30*12 -> 360 | AO30: 1 | AP30: 0.2 | AQ30: 150 | AR30: =AO30*AP30*AQ30*12 -> 360 | AT30: 1 | AU30: 0.2 | AV30: 150 | AW30: =AT30*AU30*AV30*12 -> 360
A31: 27 | B31: 양극재기술 | C31: 양극재1팀 | D31: 분석/측정 실험 | E31: 활물질 분석 | F31: SEM 분석_x000D_ | G31: 소재 이미지 분석 | H31: 샘플 홀더 자동 배출_x000D_ | I31: 샘플 홀더 배출 | R31: 연구원 | S31: 1 | T31: 0.1 | U31: 10 | V31: =S31*T31*U31*12 -> 12 | W31: 0.1 | X31: 20 | Y31: =S31*T31*X31*12 -> 24 | AE31: 2 | AF31: 2 | AG31: 12 | AH31: =AE31*AF31*AG31*12 -> 576 | AJ31: 2 | AK31: 2 | AL31: 12 | AM31: =AJ31*AK31*AL31*12 -> 576 | AO31: 2 | AP31: 2 | AQ31: 12 | AR31: =AO31*AP31*AQ31*12 -> 576 | AT31: 2 | AU31: 2 | AV31: 12 | AW31: =AT31*AU31*AV31*12 -> 576
A32: 28 | B32: 양극재기술 | C32: 양극재1팀 | D32: 분석/측정 실험 | E32: 활물질 분석 | F32: SEM 분석_x000D_ | G32: 소재 이미지 분석 | H32: 샘플 홀더 클리닝_x000D_ | I32: 샘플 홀더 클리닝 | R32: 연구원 | S32: 1 | T32: 0.05 | U32: 10 | V32: =S32*T32*U32*12 -> 6 | W32: 0.05 | X32: 20 | Y32: =S32*T32*X32*12 -> 12 | AH32: =AE32*AF32*AG32*12 -> 0 | AM32: =AJ32*AK32*AL32*12 -> 0 | AR32: =AO32*AP32*AQ32*12 -> 0 | AW32: =AT32*AU32*AV32*12 -> 0
A33: 29 | B33: 양극재기술 | C33: 양극재1팀 | D33: 분석/측정 실험 | E33: 활물질 분석 | F33: 진밀도 측정 | G33: 소재 진밀도 측정 | H33: 샘플링 및 측정 자동화 | J33: 외주 분석 진행했으나, 장비 도입으로 직접 측정 가능한 상황_x000D_ | L33: ICP 활용하여 계산 | M33: 입자 진밀도 | R33: 연구원 | S33: 0 | T33: 0 | U33: 0 | V33: =S33*T33*U33*12 -> 0 | W33: 0 | X33: 0 | Y33: =S33*T33*X33*12 -> 0 | AB33: 업체 데이터 사용 원칙이나 간혹 필요시 직접 측정. 거의 측정하지 않음 | AF33: =AC33*AD33*AE33*12 -> 0 | AK33: =AH33*AI33*AJ33*12 -> 0 | AP33: =AM33*AN33*AO33*12 -> 0 | AU33: =AR33*AS33*AT33*12 -> 0
A34: 30 | B34: 양극재기술 | C34: 양극재1팀 | D34: 샘플 제작 실험 | E34: 슬러리 제작 | F34: Slurry 제작 | G34: 전극코팅을 위한 활물질/도전재/바인더/NMP혼합된 슬러리 제조 | H34: 무게 측정 | I34: 도전재+바인더 premixing 계량 (slurry 제작 전 믹서 사용하여 미리 대량 제조). 손실 방지위해 mixing통 (Nalgene bottle)에 직접 계량 | J34: 정밀저울 | R34: 연구원 | S34: 2 | T34: 0.33 | U34: 150 | V34: =S34*T34*U34*12 -> 1188 | W34: 0.33 | X34: 180 | Y34: =S34*T34*X34*12 -> 1425.6 | Z34: 1소재, 1회 | AB34: 1명 기준으로 작성했으나, 2명이 진행 시 slurry 제조 전체 소요시간 절반으로 단축 가능 | AE34: 2 | AF34: 0.5 | AG34: 8 | AH34: =AE34*AF34*AG34*12 -> 96 | AJ34: 2 | AK34: 0.5 | AL34: 8 | AM34: =AJ34*AK34*AL34*12 -> 96 | AO34: 2 | AP34: 0.5 | AQ34: 8 | AR34: =AO34*AP34*AQ34*12 -> 96 | AT34: 2 | AU34: 0.5 | AV34: 8 | AW34: =AT34*AU34*AV34*12 -> 96
A35: 31 | B35: 양극재기술 | C35: 양극재1팀 | D35: 샘플 제작 실험 | E35: 슬러리 제작 | F35: Slurry 제작 | G35: 전극코팅을 위한 활물질/도전재/바인더/NMP혼합된 슬러리 제조 | H35: 무게 측정 | I35: 활물질 계량 (유선지 대신 Al foil 이용) 뒤 mixing통에 혼합 (슬러리 조성은 평가 양극재마다 상이) | J35: 정밀저울 | R35: 연구원 | Y35: =S35*T35*X35*12 -> 0 | AE35: 2 | AF35: 1 | AG35: 8 | AH35: =AE35*AF35*AG35*12 -> 192 | AJ35: 2 | AK35: 1 | AL35: 8 | AM35: =AJ35*AK35*AL35*12 -> 192 | AO35: 2 | AP35: 1 | AQ35: 8 | AR35: =AO35*AP35*AQ35*12 -> 192 | AT35: 2 | AU35: 1 | AV35: 8 | AW35: =AT35*AU35*AV35*12 -> 192
A36: 32 | B36: 양극재기술 | C36: 양극재1팀 | D36: 샘플 제작 실험 | E36: 슬러리 제작 | F36: Slurry 제작 | G36: 전극코팅을 위한 활물질/도전재/바인더/NMP혼합된 슬러리 제조 | H36: 고형분 맞추기 | I36: 고형분 양 고려하여 NMP 추가 투입 | J36: 정밀저울 | R36: 연구원 | Y36: =S36*T36*X36*12 -> 0 | AE36: 2 | AF36: 1.5 | AG36: 8 | AH36: =AE36*AF36*AG36*12 -> 288 | AJ36: 2 | AK36: 1.5 | AL36: 8 | AM36: =AJ36*AK36*AL36*12 -> 288 | AO36: 2 | AP36: 1.5 | AQ36: 8 | AR36: =AO36*AP36*AQ36*12 -> 288 | AT36: 2 | AU36: 1.5 | AV36: 8 | AW36: =AT36*AU36*AV36*12 -> 288
A37: 33 | B37: 양극재기술 | C37: 양극재1팀 | D37: 샘플 제작 실험 | E37: 슬러리 제작 | F37: Slurry 제작 | G37: 전극코팅을 위한 활물질/도전재/바인더/NMP혼합된 슬러리 제조 | H37: 1차 믹싱 | I37: 슬러리 1차 혼합 (thinky mixer) (믹싱 rpm 및 시간은 평가 양극재마다 상이) | J37: Thinky mixer | M37: 1350 rpm 10min 1500 rpm 3min | R37: 연구원 | Y37: =S37*T37*X37*12 -> 0 | AH37: =AE37*AF37*AG37*12 -> 0 | AM37: =AJ37*AK37*AL37*12 -> 0 | AR37: =AO37*AP37*AQ37*12 -> 0 | AW37: =AT37*AU37*AV37*12 -> 0
A38: 34 | B38: 양극재기술 | C38: 양극재1팀 | D38: 샘플 제작 실험 | E38: 슬러리 제작 | F38: Slurry 제작 | G38: 전극코팅을 위한 활물질/도전재/바인더/NMP혼합된 슬러리 제조 | H38: 뭉친부분 풀어주기 | I38: Nalgene bottle 개봉 뒤 spatula로 휘저으며 뭉친 부분 풀어주기 | J38: spatula | R38: 연구원 | Y38: =S38*T38*X38*12 -> 0 | AE38: 1 | AF38: 0.25 | AG38: 8 | AH38: =AE38*AF38*AG38*12 -> 24 | AJ38: 1 | AK38: 0.25 | AL38: 8 | AM38: =AJ38*AK38*AL38*12 -> 24 | AO38: 1 | AP38: 0.25 | AQ38: 8 | AR38: =AO38*AP38*AQ38*12 -> 24 | AT38: 1 | AU38: 0.25 | AV38: 8 | AW38: =AT38*AU38*AV38*12 -> 24
A39: 35 | B39: 양극재기술 | C39: 양극재1팀 | D39: 샘플 제작 실험 | E39: 슬러리 제작 | F39: Slurry 제작 | G39: 전극코팅을 위한 활물질/도전재/바인더/NMP혼합된 슬러리 제조 | H39: 2차 믹싱 | I39: 슬러리 2차 혼합 (thinky mixer) | J39: Thinky mixer | R39: 연구원 | Y39: =S39*T39*X39*12 -> 0 | AE39: 1 | AF39: 0.25 | AG39: 8 | AH39: =AE39*AF39*AG39*12 -> 24 | AJ39: 1 | AK39: 0.25 | AL39: 8 | AM39: =AJ39*AK39*AL39*12 -> 24 | AO39: 1 | AP39: 0.25 | AQ39: 8 | AR39: =AO39*AP39*AQ39*12 -> 24 | AT39: 1 | AU39: 0.25 | AV39: 8 | AW39: =AT39*AU39*AV39*12 -> 24
A40: 36 | B40: 양극재기술 | C40: 양극재1팀 | D40: 샘플 제작 실험 | E40: 슬러리 제작 | F40: Slurry 제작 | G40: 전극코팅을 위한 활물질/도전재/바인더/NMP혼합된 슬러리 제조 | H40: 장비 세척 및 정리 | I40: 믹싱 완료 후 장비 세척 및 정리 | R40: 연구원 | Y40: =S40*T40*X40*12 -> 0 | AE40: 1 | AF40: 0.25 | AG40: 8 | AH40: =AE40*AF40*AG40*12 -> 24 | AJ40: 1 | AK40: 0.25 | AL40: 8 | AM40: =AJ40*AK40*AL40*12 -> 24 | AO40: 1 | AP40: 0.25 | AQ40: 8 | AR40: =AO40*AP40*AQ40*12 -> 24 | AT40: 1 | AU40: 0.25 | AV40: 8 | AW40: =AT40*AU40*AV40*12 -> 24
...

Sheet 보조1_세부공정_분석
B3: LEVEL 0 | C3: LEVEL 1,2 | D3: LEVEL 2 | E3: LEVEL 3 | F3: LEVEL 4 | G3: LEVEL 5
B4: 실험 분류 | C4: 공정 | D4: 실험/분석법 상세 | E4: 실험 목적 | F4: Process step or SOP | G4: 상세 설명
C5: PSD 측정 | F5: 샘플링 | G5: 분산액 제조 (Powder + 분산제 + DI Water) powder 드라이품에서 소분, 분산제 (triton-X,1% sol) 준비, 3차 증류수 받기 -> 분산액 제조 (powder ~0.04g + 분산제 0.1ml, DI water 10g)
F6: 장비 세팅 | G6: 고형분 장비를 켠 후 DI water를 통해 background를 측정한다.
F7: 전처리 | G7: 분산액이 담긴 vial에 대해 외부 초음파 처리 1min
F8: 샘플 loading 및 측정 | G8: 장비에 분산액 투입 및 측정 시작
F9: 장비 세척 및 정리 | G9: 측정 장비를 세척한다.
F10: Data 정리 | G10: data 추출 (vol. /Num. 기준 각각) 및 정리/그래프 그리기, (측정 및 클리닝에 사용되는 폐수 주기적으로 별도 폐기 필요)
C11: SEM 분석 | F11: 샘플링 | G11: 샘플홀더에 카본테이브 부착 후, 소량의 powder (혹은 전극) 부착
F12: 샘플 홀더 장비로 투입 | G12: 샘플 홀더 장비로 투입
F13: 이미지 생성 | G13: 원하는 샘플 SEM 이미지 (입자의 형태를 잘 확인할 수 있는) 확인 후 배율별로 각각 캡쳐
F14: EDS 분석_x000D_ | G14: EDS 분석
F15: Data 저장_x000D_ | G15: Data 저장 후 추출
F16: 샘플 홀더 자동 배출_x000D_ | G16: 샘플 홀더 배출
F17: 샘플 홀더 클리닝_x000D_ | G17: 샘플 홀더 클리닝
C18: SEM 분석 (이온밀링) | F18: 이온밀링_x000D_ | G18: 일부 연구원들은 라이선스를 받아 직접 측정하기도 하나, quality있는 분석과 결과를 위해 분석담당에 분석 의뢰 중
F19: 전극 단면 분석 (SEM/EDS) | G19: 26년 기준 시료 ~20개 의뢰
C20: 슬러리 유변물성 측정 | F20: 샘플링 | G20: 주사기에 슬러리 11ml 샘플링 (샘플 1종당 4개) 후 1개를 제외하고 3개는 상온 챔버에 보관
F21: calibraton | G21: 장비 calibration 진행 -> geomerty 장착 후 calibration 추가 진행 (장비 오류 확인 작업), 4회 반복 (0, 1, 2, 7일)
F22: 슬러리 투입 | G22: 주사기로 슬러리 9-11ml 투입 후 측정 조건/저장 setting
F23: 슬러리 유변물성 측정 | G23: 유변 물성 측정 (시퀀스에 따라 측정소요 시간 달라짐)
F24: Data 정리 | G24: data 추출 및 초기 점도 대비 1, 2, 7일차 점도 변화율 계산/정리 (data 정리는 동일 시료 한번에 정리)
F25: 장비 세척 및 정리 | G25: 사용한 장비 세척
C26: XRD | F26: 샘플 소분 | G26: 시료 소분 후 분석실 이동
F27: 샘플링 | G27: ①샘플 홀더에 powder 평평하게 샘플링 ② 홀더 주변 클리닝 (에틸알콜 등), ③ 홀더에 샘플명/이름/날짜 수기로 기입, ④ 샘플 홀더 장비에 투입 후 측정 패턴 및 저장 setting
F28: XRD 측정 | G28: XRD 측정
F29: Data 변환 및 fitting | G29: ① Topaz 프로그램 활용하여 Rietveld refinement진행, 필요 데이터 계산 및 추출 (strain, crystal density, lattice parameter, cation mixing, X-size) ② EVA 프로그램 활용하여 (003), (104) peak FWHM 계산 및 추출, raw data는 xy형식 파일로 저장하여 추출 / 결정립 fitting ③xy파일로 raw data불러와 origin 또는 MDS이용해 그래프 생성
F30: 장비 세척 및 정리 | G30: 사용한 샘플홀더 세척 및 정리
F31: 그래프 생성 | G31: 추출한 data로 그래프 생성
C32: BET | F32: 샘플링 | G32: 비어있는 BET 초자의 무게 측정 -> 초자에 샘플 투입 (powder 0.2~2g/밀도가 낮은 샘플은 g수를 더 낮춰서 투입) -> 초자 neck부분에 묻어있는 시료는 면봉으로 닦아주기, 전처리 장비에 초자 연결
F33: 전처리_x000D_ | G33: 300℃ 진공상태에서 2시간동안 전처리 진행 (pore V.이 큰 원료의 경우, 전처리 시간 증가) --> 상온으로 식히기
F34: 무게 측정_x000D_ | G34: 전처리 진행한 샘플이 담긴 BET 초자의 무게 측정-> 샘플 무게 계산
F35: 측정 준비 | G35: BET 장비에 초자 장착 -> 가스보관실에서 액체 질소 소분 후 장비 용기에 덜어주기, 측정 패턴/파일명 등 설정
F36: 측정 | G36: 측정 시작 (장비에 따라 2개 소재 동시 분석 가능)
F37: Data 정리 | G37: data 추출 및 정리 (그래프 그리기, pore 크기별 비율 계산 등)
F38: 장비 세척 및 정리 | G38: 사용한 초자 세척 및 정리
C39: Tap 밀도 | F39: 샘플링 | G39: 메스실린더에 시료 40g 계량 후 투입 및 tap밀도 측정기에 장착
F40: 1000회 tapping | G40: 1000회 tapping
F41: Tap 밀도 측정 | G41: 메스실린더 부피 확인 및 tap 밀도 계산
F42: 장비 세척 및 정리 | G42: 사용한 메스실린더 세척 및 정리
...

Sheet 보조2_세부공정_실험
B3: LEVEL 0 | C3: LEVEL 1,2 | D3: LEVEL 2 | E3: LEVEL 3 | F3: LEVEL 4 | G3: LEVEL 5
B4: 실험 분류 | C4: 공정 | D4: 실험/분석법 상세 | E4: 실험 목적 | F4: Process step or SOP | G4: 상세 설명
C5: 슬러리 제작 | D5: 양극 슬러리 제작 | F5: 1차 재료 계량 | G5: 도전재+바인더 premixing 계량 (slurry 제작 전 믹서 사용하여 미리 대량 제조). 손실 방지위해 mixing통 (Nalgene bottle)에 직접 계량
F6: 2차 계량 | G6: 활물질 계량 (유선지 대신 Al foil 이용) 뒤 mixing통에 혼합 (슬러리 조성은 평가 양극재마다 상이)
F7: 고형분 맞추기 | G7: 고형분 양 고려하여 NMP 추가 투입
F8: 1차 믹싱 | G8: 슬러리 1차 혼합 (thinky mixer) (믹싱 rpm 및 시간은 평가 양극재마다 상이)
F9: 뭉친부분 풀어주기 | G9: Nalgene bottle 개봉 뒤 spatula로 휘저으며 뭉친 부분 풀어주기
F10: 2차 믹싱 | G10: 슬러리 2차 혼합 (thinky mixer)
F11: 장비 세척 및 정리 | G11: 믹싱 완료 후 장비 세척 및 정리
D12: 음극 슬러리 제작 (코인셀용_음극재1팀) | F12: 소재 준비 | G12: 흑연 및 Si계 활물질, Super C, 바인더, DI water 준비 | H12: 음극재 1팀 특수실험
F13: 슬러리 믹싱 | G13: ZrO2 ball 포함/Step별 mixing을 통한 슬러리 제조 | H13: 음극재 1팀 특수실험
F14: 장비 세척 및 정리 | G14: 믹싱 완료 후 장비 세척 및 정리 | H14: 음극재 1팀 특수실험
D15: 음극 슬러리 제작 | F15: 소재준비 | G15: 흑연 및 Si계 활물질, Super C, 바인더, DI water 준비
F16: 1차 슬러리 믹싱 | G16: PE bottle에 도전재(Super C65), CMC (Daicel2200 1.5%), 물 계량 후 homodisper로 분산
F17: 2차 슬러리 믹싱 | G17: 드라이룸에서 Si 시료 소분, TK 전용 믹서용기에 활물질 (흑연: Si계 혼합)+Super C 분산액, DI water 투입 후 고점도 mixing
F18: 3차 슬러리 믹싱 | G18: SWCNT 추가 투입하여 TK mixer에서 20분 믹싱 --> CMC 추가 투입 후 TK mixer 5min -> homodisper로 옮겨 25분 추가 분산
F19: 4차 슬러리 믹싱 | G19: 바인더 및 물 투입후 10분 추가 분산
F20: 장비 세척 및 정리 | G20: 믹싱 완료 후 장비 세척 및 정리
C21: 전극 제작 | D21: 양극 전극 제작 | F21: 소재준비 (이송) | G21: 양극 슬러리 준비
F22: 코팅 | G22: 슬러리를 Al foil 위에 도포한 후, 목표 전극무게 (~420mg/25cm2) 수준이 되도록 doctor blade gap 조절하여 코팅
F23: 건조 | G23: 코팅된 Al foil이 들뜨거나 기울어져 슬러리 로딩 불균일이 발생하지 않도록 건조과정 동안 고정 필요
F24: 장비 세척 및 정리 | G24: 사용한 코터 세척 및 정리
F25: 압연 | G25: 2cm 폭으로 전극 cutting 뒤 target porosity에 맞게 압연기 gap 조절하여 압연 2회 진행 (lab설비 기준)
F26: 장비 세척 및 정리 | G26: 사용한 압연기 세척 및 정리
D27: 음극 전극 제작 (코인셀용_음극재1팀) | F27: 소재 준비 | G27: 음극 슬러리 준비 | H27: 음극재 1팀 특수실험
F28: 코팅 | G28: foil frame에 Cu foil을 끼운 후, coater에 장착, gap 조절이 필요한 경우, 조절 후 Knife 장착, 슬러리 도포 후 코팅 시작 | H28: 음극재 1팀 특수실험
F29: 건조 | G29: foil frame에서 코팅 전극 제거 후 건조 챔버에 투입하여 60도 30분 이상 건조 | H29: 음극재 1팀 특수실험
F30: 장비 세척 및 정리 | G30: 사용한 코터 세척 및 정리 | H30: 음극재 1팀 특수실험
F31: 압연 | G31: 3cm 폭으로 전극 cutting 뒤 target porosity에 맞게 압연기 gap 조절하여 압연 진행 | H31: 음극재 1팀 특수실험
F32: 장비 세척 및 정리 | G32: 사용한 압연기 세척 및 정리 | H32: 음극재 1팀 특수실험
D33: 음극 전극 제작 | F33: 소재 준비 | G33: 음극 슬러리 준비
F34: 코팅 및 건조 | G34: 코팅룸 이동, 코터 On -> 건조하고자 하는 온도 및 코터속도 setting -> 코팅 준비 (슬러리 투입 및 폭에 맞춰 댐 setting) (목표 온도 도달까지 대기 시간 포함) ->슬러리 투입 후 코팅 gap 조절 -> 건조되어 나온 코팅 전극 무게 확인 (무게 로딩이 맞지 않는다면 gap 조절 반복) -> target 로딩에서 필요한 양만큼 전극 코팅 진행
F35: 장비 세척 및 정리 | G35: 사용한 코터 세척 및 정리
F36: 압연 | G36: 3-7cm 폭으로 전극 cutting 뒤 target porosity에 맞게 압연기 gap 조절하여 압연 진행
F37: 장비 세척 및 정리 | G37: 사용한 압연기 세척 및 정리
C38: 셀 제작_코인셀 | D38: 소재 준비 | F38: Ni foam cutting | G38: 2~2.5cm 폭으로 Ni foam cutting
F39: Ni foam press | G39: ~250㎛ 두께로 press
F40: Ni foam 타발 | G40: Ni foam 타발
F41: Ni foam 세척/건조 | G41: 이물질 제거 등을 위해 에틸알콜+초음파 세척 및 건조 (정리 포함)
F42: 코인셀용 양/음극 타발 | G42: 코인셀용 양/음극 타발 (1소재당 코인셀 4~5개 제조)
...

Sheet 보조1-1_세부공정_분석_양극재
B3: LEVEL 0 | C3: LEVEL 1,2 | D3: LEVEL 2 | E3: LEVEL 3 | F3: LEVEL 4 | G3: LEVEL 5
B4: 실험 분류 | C4: 공정 | D4: 실험/분석법 상세 | E4: 실험 목적 | F4: Process step or SOP | G4: 상세 설명
C5: PSD 측정 | F5: 샘플링 | G5: 장비 세팅 분산제 투입 (10방울) 및 measure background 클릭
F6: 외부 초음파 | G6: 파우더 전처리 파우더 투입 후 초음파 처리 (소듐 양극재의 경우 파우더와 분산제 미리 혼합하여 선분산액 제조 필요)
F7: 입도 측정 | G7: 측정 (3회)
F8: 장비 세척 | G8: 측정 장비를 세척한다.
F9: Data 정리 | G9: Data 추출 (vol. /Num. 기준 각각) 및 정리/그래프 그리기, (측정 및 클리닝에 사용되는 폐수 주기적으로 별도 폐기 필요)
C10: SEM 분석 | F10: 샘플링 | G10: 샘플홀더에 카본테이브 부착 후, 소량의 powder (혹은 전극) 부착
F11: 샘플 홀더 장비로 투입 | G11: 분석실로 이동+샘플 홀더 장비로 투입
F12: 이미지 생성 | G12: 원하는 샘플 SEM 이미지 (입자의 형태를 잘 확인할 수 있는) 확인 후 배율별로 각각 캡쳐 (배율별, SE/BSE 모드 각각 촬영)
F13: EDS 분석_x000D_ | G13: EDS 분석
F14: Data 저장_x000D_ | G14: Data 저장 후 추출
F15: 샘플 홀더 자동 배출_x000D_ | G15: 샘플 홀더 배출
F16: 샘플 홀더 클리닝_x000D_ | G16: 샘플 홀더 클리닝
C17: 이온밀링 | F17: 샘플링 | G17: 홀더에 carbon tape 부착 뒤 전극 loading
F18: 샘플링 | G18: 이온밀링 홀더에 샘플 결착 후 광학현미경으로 보며 샘플 위치 정밀 조정
F19: 샘플 홀더 장비로 투입 | G19: 이온밀링 챔버 오픈 및 결착
F20: 이온밀링 | G20: 이온밀링 챔버 vacuum 뒤 이온밀링 시행
C21: XRD | F21: 샘플링 | G21: 드라이룸에서 시료 소분 후 분석실 이동 --> 샘플 홀더에 powder 평평하게 샘플링 (한 소재당 1개의 시료/1회 측정), 홀더 주변 클리닝 (에틸알콜 등), 홀더에 샘플명/이름/날짜 수기로 기입, 샘플 홀더 장비에 투입 후 측정 패턴 및 저장 setting
F22: XRD 측정 | G22: XRD 측정
F23: Data 변환 및 fitting | G23: 분석실 이동 + XRD 측정 컴퓨터에 있는 Eva/ topas 프로그램을 이용하여 data 변환 및 추출
F24: 세척 및 정리 | G24: 사용한 샘플홀더 세척 및 정리
F25: 그래프 생성 | G25: 추출한 data로 그래프 생성
C26: BET | F26: 샘플링 | G26: 업체 데이터 사용중
F27: 전처리_x000D_
F28: 무게 측정_x000D_
F29: 측정 준비
F30: 측정
F31: Data 정리
F32: 장비 세척 및 정리
C33: Tap 밀도 | F33: 샘플링 | G33: 업체 데이터 사용중
F34: 1000회 tapping
F35: Tap 밀도 측정
F36: 장비 세척 및 정리
C37: 진밀도 측정 | F37: 샘플링 | G37: 외주 분석 진행중
F38: 측정
F39: Data 정리
F40: 장비 세척 및 정리
C41: 압연 밀도 분석 (Pallet density) | F41: 장비 세팅 | G41: 장비세팅 장비에 빈 몰드 로딩 뒤 원점 측정. (같은 몰드 사용한 연속측정 시 본 step 생략)
F42: 무게 측정 | G42: 계량 몰드 회수 후 파우더 계량 (2ton: 5.0g, 9ton: 3.0g)
...

Sheet 보조1-2_세부공정_분석_리사이클
B3: LEVEL 0 | C3: LEVEL 1,2 | D3: LEVEL 2 | E3: LEVEL 3 | F3: LEVEL 4 | G3: LEVEL 5
B4: 실험 분류 | C4: 공정 | D4: 실험/분석법 상세 | E4: 실험 목적 | F4: Process step or SOP | G4: 상세 설명
C5: BET 측정 | F5: 샘플링 | G5: 비어있는 BET 초자의 무게 측정 -> 초자에 샘플 투입 (powder 0.2~2g/밀도가 낮은 샘플은 g수를 더 낮춰서 투입) -> 초자 neck부분에 묻어있는 시료는 면봉으로 닦아주기, 전처리 장비에 초자 연결
F6: 전처리 | G6: 300℃ 진공상태에서 2시간동안 전처리 진행 (pore V.이 큰 원료의 경우, 전처리 시간 증가) --> 상온으로 식히기
F7: 무게 측정 | G7: 전처리 진행한 샘플이 담긴 BET 초자의 무게 측정-> 샘플 무게 계산
F8: 튜브장착 및 액체질소 투입 | G8: BET 장비에 초자 장착 -> 가스보관실에서 액체 질소 소분 후 장비 용기에 덜어주기, 측정 패턴/파일명 등 설정
F9: 측정 | G9: 측정 시작 (장비에 따라 2개 소재 동시 분석 가능)
F10: Data 정리 | G10: data 추출 및 정리 (그래프 그리기, pore 크기별 비율 계산 등)
F11: 세척 및 정리 | G11: 사용한 초자 세척 및 정리
C12: PSD 분석 | F12: 샘플링 | G12: 양극재 powder 드라이품에서 소분, 분산제 (triton-X,1% sol) 준비, 3차 증류수 받기 -> 분산액 제조 (powder ~0.04g + 분산제 0.1ml, DI water 10g)
F13: 장비세팅 | G13: 고형분 장비를 켠 후 DI water를 통해 background를 측정한다.
F14: 전처리 | G14: 분산액이 담긴 vial에 대해 외부 초음파 처리 2min
F15: 샘플 loading 및 측정 | G15: 장비에 분산액 투입 및 측정 시작 (현재 SOP는 기본 3회 측정으로 setting 되어 있음)
F16: 장비 세척 및 정리 | G16: 측정 장비를 세척한다.
F17: Data 정리 | G17: data 추출 (vol. /Num. 기준 각각) 및 정리/그래프 그리기, (측정 및 클리닝에 사용되는 폐수 주기적으로 별도 폐기 필요)
C18: PD 측정기 (HAN TECH CO.) | F18: 장비 calibration | G18: 샘플 loading 되지 않은 몰드를 이용하여 9ton까지 pressing 하며 calibration
F19: 몰드 내 샘플 투입 및 장비 투입 | G19: 1g의 활물질 파우더를 정량하여 몰드에 넣어준 후 장비에 loading
F20: 샘플 측정 | G20: 1 ~ 9 ton, 1ton 간격으로 압연 두께 측정 및 데이터 기록
F21: 클리닝 | G21: 클리닝
C22: XRD 분석 | F22: 샘플링 | G22: 드라이룸에서 시료 소분 후 분석실 이동 --> 샘플 홀더에 powder 평평하게 샘플링 (한 소재당 3개의 시료/1회 측정), 홀더 주변 클리닝 (에틸알콜 등), 홀더에 샘플명/이름/날짜 수기로 기입, 샘플 홀더 장비에 투입 후 측정 패턴 및 저장 setting - 현재 리사이클팀은 powder 위주 분석 중
F23: XRD 측정 | G23: XRD 측정
F24: Data 변환 및 fitting | G24: 분석실 이동 + XRD 측정 컴퓨터에 있는 Eva/ topas 프로그램을 이용하여 data 변환 및 추출
F25: 세척 및 정리 | G25: 사용한 샘플홀더 세척 및 정리
F26: 그래프 생성 | G26: 추출한 data로 그래프 생성
C27: SEM 분석 | F27: 샘플링 | G27: 샘플홀더에 카본테이프 부착 후, 소량의 powder (혹은 전극) 부착
F28: 샘플 홀더 장비로 투입 | G28: 분석실로 이동+샘플 홀더 장비로 투입
F29: 이미지 생성 | G29: 원하는 샘플 SEM 이미지 (입자의 형태를 잘 확인할 수 있는) 확인 후 배율별로 각각 캡쳐 (배율별, SE/BSE 모드 각각 촬영)
F30: EDS 분석 | G30: EDS 분석
F31: Data 저장 | G31: Data 저장 후 추출
F32: 샘플 홀더 자동 배출 | G32: 샘플 홀더 배출
F33: 샘플 홀더 클리닝 | G33: 샘플 홀더 클리닝
C34: SEM 분석(이온밀링) | F34: 이온밀링 | G34: 일부 연구원들은 라이선스를 받아 직접 측정하기도 하나, quality있는 분석과 결과를 위해 분석담당에 분석 의뢰 중
F35: 전극 단면 분석 (SEM/EDS) | G35: 26년 기준 시료 ~20개 의뢰
C36: 수분 함량 측정 | F36: 샘플링 | G36: 전용 바이알에 시료 1g 소분
F37: 빈 바이알과 샘플소분한 바이알 장착 | G37: Karl Fischer 장비에 위치시킴. (빈 병의 수분 측정 위한 1개 포함)
F38: 측정 온도 조건 설정 | G38: 원하는 측정 온도 조건 설정
F39: Calibration | G39: 수분함량 측정 시작 후 장비에 연결된 비커 내 용액의 상태 칼리브레이션 시작
F40: 측정 | G40: 장비가 설정한 시료의 개수만큼 자동으로 위치 바꿔가며 측정함.
F41: Data 정리 | G41: data 저장 후 추출
F42: 세척 및 정리 | G42: 세척및 정리
...

Sheet 보조1-3_세부공정_분석_전구체
B3: LEVEL 0 | C3: LEVEL 1,2 | D3: LEVEL 2 | E3: LEVEL 3 | F3: LEVEL 4 | G3: LEVEL 5
B4: 실험 분류 | C4: 공정 | D4: 실험/분석법 상세 | E4: 실험 목적 | F4: Process step or SOP | G4: 상세 설명
C5: PSD 측정 | F5: 샘플링 | G5: 분산액 제조 (Powder + 분산제 + DI Water) powder 드라이품에서 소분, 분산제 (triton-X,1% sol) 준비, 3차 증류수 받기 -> 분산액 제조 (powder ~0.04g + 분산제 0.1ml, DI water 10g)
F6: 장비 세팅 | G6: 고형분 장비를 켠 후 DI water를 통해 background를 측정한다.
F7: 전처리 | G7: 분산액이 담긴 vial에 대해 외부 초음파 처리 1min
F8: 샘플 loading 및 측정 | G8: 장비에 분산액 투입 및 측정 시작
F9: 장비 세척 및 정리 | G9: 측정 장비를 세척한다.
F10: Data 정리 | G10: data 추출 (vol. /Num. 기준 각각) 및 정리/그래프 그리기, (측정 및 클리닝에 사용되는 폐수 주기적으로 별도 폐기 필요)
C11: SEM 분석 | F11: 샘플링 | G11: 샘플홀더에 카본테이브 부착 후, 소량의 powder (혹은 전극) 부착
F12: 샘플 홀더 장비로 투입 | G12: 샘플 홀더 장비로 투입
F13: 이미지 생성 | G13: 원하는 샘플 SEM 이미지 (입자의 형태를 잘 확인할 수 있는) 확인 후 배율별로 각각 캡쳐
F14: EDS 분석_x000D_ | G14: EDS 분석
F15: Data 저장_x000D_ | G15: Data 저장 후 추출
F16: 샘플 홀더 자동 배출_x000D_ | G16: 샘플 홀더 배출
F17: 샘플 홀더 클리닝_x000D_ | G17: 샘플 홀더 클리닝
C18: SEM 분석 (이온밀링) | F18: 이온밀링_x000D_ | G18: 일부 연구원들은 라이선스를 받아 직접 측정하기도 하나, quality있는 분석과 결과를 위해 분석담당에 분석 의뢰 중
F19: 전극 단면 분석 (SEM/EDS) | G19: 26년 기준 시료 ~20개 의뢰
C20: XRD | F20: 샘플 소분 | G20: 시료 소분 후 분석실 이동
F21: 샘플링 | G21: ①샘플 홀더에 powder 평평하게 샘플링 ② 홀더 주변 클리닝 (에틸알콜 등), ③ 홀더에 샘플명/이름/날짜 수기로 기입, ④ 샘플 홀더 장비에 투입 후 측정 패턴 및 저장 setting
F22: XRD 측정 | G22: XRD 측정
F23: Data 변환 및 fitting | G23: ① Topaz 프로그램 활용하여 Rietveld refinement진행, 필요 데이터 계산 및 추출 (strain, crystal density, lattice parameter, cation mixing, X-size) ② EVA 프로그램 활용하여 (003), (104) peak FWHM 계산 및 추출, raw data는 xy형식 파일로 저장하여 추출 / 결정립 fitting ③xy파일로 raw data불러와 origin 또는 MDS이용해 그래프 생성
F24: 장비 세척 및 정리 | G24: 사용한 샘플홀더 세척 및 정리
F25: 그래프 생성 | G25: 추출한 data로 그래프 생성
C26: BET | F26: 샘플링 | G26: 비어있는 BET 초자의 무게 측정 -> 초자에 샘플 투입 (powder 0.2~2g/밀도가 낮은 샘플은 g수를 더 낮춰서 투입) -> 초자 neck부분에 묻어있는 시료는 면봉으로 닦아주기, 전처리 장비에 초자 연결
F27: 전처리_x000D_ | G27: 300℃ 진공상태에서 2시간동안 전처리 진행 (pore V.이 큰 원료의 경우, 전처리 시간 증가) --> 상온으로 식히기
F28: 무게 측정_x000D_ | G28: 전처리 진행한 샘플이 담긴 BET 초자의 무게 측정-> 샘플 무게 계산
F29: 측정 준비 | G29: BET 장비에 초자 장착 -> 가스보관실에서 액체 질소 소분 후 장비 용기에 덜어주기, 측정 패턴/파일명 등 설정
F30: 측정 | G30: 측정 시작 (장비에 따라 2개 소재 동시 분석 가능)
F31: Data 정리 | G31: data 추출 및 정리 (그래프 그리기, pore 크기별 비율 계산 등)
F32: 장비 세척 및 정리 | G32: 사용한 초자 세척 및 정리
C33: Tap 밀도 | F33: 샘플링 | G33: 메스실린더에 시료 40g 계량 후 투입 및 tap밀도 측정기에 장착
F34: 1000회 tapping | G34: 1000회 tapping
F35: Tap 밀도 측정 | G35: 메스실린더 부피 확인 및 tap 밀도 계산
F36: 장비 세척 및 정리 | G36: 사용한 메스실린더 세척 및 정리
C37: 진밀도 측정 | F37: 샘플링 | G37: 드라이룸에서 시료 소분 후, 진밀도 전용기에 분체 투입 후 tapping, cap 장착, 측정 조건 및 횟수 등 설정 (온도 안정화 될때까지 대기)
F38: 측정 | G38: 진밀도 측정
F39: Data 정리 | G39: data 추출
F40: 장비 세척 및 정리 | G40: 사용한 초자 세척 및 정리
C42: 전구체팀 특수 실험
C43: 압연 밀도 | F43: 장비 세팅 | G43: 장비에 빈 몰드 로딩 뒤 원점 측정. (같은 몰드 사용한 연속측정 시 본 step 생략)
...

Sheet 보조1-4_세부공정_분석_양극재선행
B3: LEVEL 0 | C3: LEVEL 1,2 | D3: LEVEL 2 | E3: LEVEL 3 | F3: LEVEL 4 | G3: LEVEL 5
B4: 실험 분류 | C4: 공정 | D4: 실험/분석법 상세 | E4: 실험 목적 | F4: Process step or SOP | G4: 상세 설명
C5: PSD 측정 | F5: 샘플링 | G5: 분산액 제조 (Powder + 분산제 + DI Water) powder 드라이품에서 소분, 분산제 (triton-X,1% sol) 준비, 3차 증류수 받기 -> 분산액 제조 (powder ~0.04g + 분산제 0.1ml, DI water 10g)
F6: 장비 세팅 | G6: 고형분 장비를 켠 후 DI water를 통해 background를 측정한다.
F7: 전처리 | G7: 분산액이 담긴 vial에 대해 외부 초음파 처리 1min
F8: 샘플 loading 및 측정 | G8: 장비에 분산액 투입 및 측정 시작
F9: 장비 세척 및 정리 | G9: 측정 장비를 세척한다.
F10: Data 정리 | G10: data 추출 (vol. /Num. 기준 각각) 및 정리/그래프 그리기, (측정 및 클리닝에 사용되는 폐수 주기적으로 별도 폐기 필요)
C11: SEM 분석 | F11: 샘플링 | G11: 샘플홀더에 카본테이브 부착 후, 소량의 powder (혹은 전극) 부착
F12: 샘플 홀더 장비로 투입 | G12: 샘플 홀더 장비로 투입
F13: 이미지 생성 | G13: 원하는 샘플 SEM 이미지 (입자의 형태를 잘 확인할 수 있는) 확인 후 배율별로 각각 캡쳐
F14: EDS 분석_x000D_ | G14: EDS 분석
F15: Data 저장_x000D_ | G15: Data 저장 후 추출
F16: 샘플 홀더 자동 배출_x000D_ | G16: 샘플 홀더 배출
F17: 샘플 홀더 클리닝_x000D_ | G17: 샘플 홀더 클리닝
C18: SEM 분석 (이온밀링) | F18: 이온밀링_x000D_ | G18: 일부 연구원들은 라이선스를 받아 직접 측정하기도 하나, quality있는 분석과 결과를 위해 분석담당에 분석 의뢰 중
F19: 전극 단면 분석 (SEM/EDS) | G19: 26년 기준 시료 ~20개 의뢰
C20: XRD | F20: 샘플 소분 | G20: 시료 소분 후 분석실 이동
F21: 샘플링 | G21: ①샘플 홀더에 powder 평평하게 샘플링 ② 홀더 주변 클리닝 (에틸알콜 등), ③ 홀더에 샘플명/이름/날짜 수기로 기입, ④ 샘플 홀더 장비에 투입 후 측정 패턴 및 저장 setting
F22: XRD 측정 | G22: XRD 측정
F23: Data 변환 및 fitting | G23: ① Topaz 프로그램 활용하여 Rietveld refinement진행, 필요 데이터 계산 및 추출 (strain, crystal density, lattice parameter, cation mixing, X-size) ② EVA 프로그램 활용하여 (003), (104) peak FWHM 계산 및 추출, raw data는 xy형식 파일로 저장하여 추출 / 결정립 fitting ③xy파일로 raw data불러와 origin 또는 MDS이용해 그래프 생성
F24: 장비 세척 및 정리 | G24: 사용한 샘플홀더 세척 및 정리
F25: 그래프 생성 | G25: 추출한 data로 그래프 생성
C26: BET | F26: 샘플링 | G26: 비어있는 BET 초자의 무게 측정 -> 초자에 샘플 투입 (powder 0.2~2g/밀도가 낮은 샘플은 g수를 더 낮춰서 투입) -> 초자 neck부분에 묻어있는 시료는 면봉으로 닦아주기, 전처리 장비에 초자 연결
F27: 전처리_x000D_ | G27: 300℃ 진공상태에서 2시간동안 전처리 진행 (pore V.이 큰 원료의 경우, 전처리 시간 증가) --> 상온으로 식히기
F28: 무게 측정_x000D_ | G28: 전처리 진행한 샘플이 담긴 BET 초자의 무게 측정-> 샘플 무게 계산
F29: 측정 준비 | G29: BET 장비에 초자 장착 -> 가스보관실에서 액체 질소 소분 후 장비 용기에 덜어주기, 측정 패턴/파일명 등 설정
F30: 측정 | G30: 측정 시작 (장비에 따라 2개 소재 동시 분석 가능)
F31: Data 정리 | G31: data 추출 및 정리 (그래프 그리기, pore 크기별 비율 계산 등)
F32: 장비 세척 및 정리 | G32: 사용한 초자 세척 및 정리
C33: Tap 밀도 | F33: 샘플링 | G33: 메스실린더에 시료 40g 계량 후 투입 및 tap밀도 측정기에 장착
F34: 1000회 tapping | G34: 1000회 tapping
F35: Tap 밀도 측정 | G35: 메스실린더 부피 확인 및 tap 밀도 계산
F36: 장비 세척 및 정리 | G36: 사용한 메스실린더 세척 및 정리
C37: 진밀도 측정 | F37: 샘플링 | G37: 드라이룸에서 시료 소분 후, 진밀도 전용기에 분체 투입 후 tapping, cap 장착, 측정 조건 및 횟수 등 설정 (온도 안정화 될때까지 대기)
F38: 측정 | G38: 진밀도 측정
F39: Data 정리 | G39: data 추출
F40: 장비 세척 및 정리 | G40: 사용한 초자 세척 및 정리
C42: 양그재선행팀 특수 실험
C43: 압연 밀도 | F43: 장비 세팅 | G43: 장비에 빈 몰드 로딩 뒤 원점 측정. (같은 몰드 사용한 연속측정 시 본 step 생략)
...

Sheet 보조1-5_세부공정_분석_음극재
B3: LEVEL 0 | C3: LEVEL 1,2 | D3: LEVEL 2 | E3: LEVEL 3 | F3: LEVEL 4 | G3: LEVEL 5
B4: 실험 분류 | C4: 공정 | D4: 실험/분석법 상세 | E4: 실험 목적 | F4: Process step or SOP | G4: 상세 설명
C5: PSD 측정 | F5: 샘플링 | G5: 분산액 제조 (Powder + 분산제 + DI Water) powder 드라이품에서 소분, 분산제 (triton-X,1% sol) 준비, 3차 증류수 받기 -> 분산액 제조 (powder ~0.04g + 분산제 0.1ml, DI water 10g)
F6: 장비 세팅 | G6: 고형분 장비를 켠 후 DI water를 통해 background를 측정한다.
F7: 전처리 | G7: 분산액이 담긴 vial에 대해 외부 초음파 처리 1min
F8: 샘플 loading 및 측정 | G8: 장비에 분산액 투입 및 측정 시작
F9: 장비 세척 및 정리 | G9: 측정 장비를 세척한다.
F10: Data 정리 | G10: data 추출 (vol. /Num. 기준 각각) 및 정리/그래프 그리기, (측정 및 클리닝에 사용되는 폐수 주기적으로 별도 폐기 필요)
C11: SEM 분석 | F11: 샘플링 | G11: 샘플홀더에 카본테이브 부착 후, 소량의 powder (혹은 전극) 부착
F12: 샘플 홀더 장비로 투입 | G12: 샘플 홀더 장비로 투입
F13: 이미지 생성 | G13: 원하는 샘플 SEM 이미지 (입자의 형태를 잘 확인할 수 있는) 확인 후 배율별로 각각 캡쳐
F14: EDS 분석_x000D_ | G14: EDS 분석
F15: Data 저장_x000D_ | G15: Data 저장 후 추출
F16: 샘플 홀더 자동 배출_x000D_ | G16: 샘플 홀더 배출
F17: 샘플 홀더 클리닝_x000D_ | G17: 샘플 홀더 클리닝
C18: SEM 분석 (이온밀링) | F18: 이온밀링_x000D_ | G18: 일부 연구원들은 라이선스를 받아 직접 측정하기도 하나, quality있는 분석과 결과를 위해 분석담당에 분석 의뢰 중
F19: 전극 단면 분석 (SEM/EDS) | G19: 26년 기준 시료 ~20개 의뢰
C20: 슬러리 유변물성 측정 | F20: 샘플링 | G20: 주사기에 슬러리 11ml 샘플링 (샘플 1종당 4개) 후 1개를 제외하고 3개는 상온 챔버에 보관
F21: calibraton | G21: 장비 calibration 진행 -> geomerty 장착 후 calibration 추가 진행 (장비 오류 확인 작업), 4회 반복 (0, 1, 2, 7일)
F22: 슬러리 투입 | G22: 주사기로 슬러리 9-11ml 투입 후 측정 조건/저장 setting
F23: 슬러리 유변물성 측정 | G23: 유변 물성 측정 (시퀀스에 따라 측정소요 시간 달라짐)
F24: Data 정리 | G24: data 추출 및 초기 점도 대비 1, 2, 7일차 점도 변화율 계산/정리 (data 정리는 동일 시료 한번에 정리)
F25: 장비 세척 및 정리 | G25: 사용한 장비 세척
C26: XRD | F26: 샘플 소분 | G26: 시료 소분 후 분석실 이동
F27: 샘플링 | G27: ①샘플 홀더에 powder 평평하게 샘플링 ② 홀더 주변 클리닝 (에틸알콜 등), ③ 홀더에 샘플명/이름/날짜 수기로 기입, ④ 샘플 홀더 장비에 투입 후 측정 패턴 및 저장 setting
F28: XRD 측정 | G28: XRD 측정
F29: Data 변환 및 fitting | G29: ① Topaz 프로그램 활용하여 Rietveld refinement진행, 필요 데이터 계산 및 추출 (strain, crystal density, lattice parameter, cation mixing, X-size) ② EVA 프로그램 활용하여 (003), (104) peak FWHM 계산 및 추출, raw data는 xy형식 파일로 저장하여 추출 / 결정립 fitting ③xy파일로 raw data불러와 origin 또는 MDS이용해 그래프 생성
F30: 장비 세척 및 정리 | G30: 사용한 샘플홀더 세척 및 정리
F31: 그래프 생성 | G31: 추출한 data로 그래프 생성
C32: BET | F32: 샘플링 | G32: 비어있는 BET 초자의 무게 측정 -> 초자에 샘플 투입 (powder 0.2~2g/밀도가 낮은 샘플은 g수를 더 낮춰서 투입) -> 초자 neck부분에 묻어있는 시료는 면봉으로 닦아주기, 전처리 장비에 초자 연결
F33: 전처리_x000D_ | G33: 300℃ 진공상태에서 2시간동안 전처리 진행 (pore V.이 큰 원료의 경우, 전처리 시간 증가) --> 상온으로 식히기
F34: 무게 측정_x000D_ | G34: 전처리 진행한 샘플이 담긴 BET 초자의 무게 측정-> 샘플 무게 계산
F35: 측정 준비 | G35: BET 장비에 초자 장착 -> 가스보관실에서 액체 질소 소분 후 장비 용기에 덜어주기, 측정 패턴/파일명 등 설정
F36: 측정 | G36: 측정 시작 (장비에 따라 2개 소재 동시 분석 가능)
F37: Data 정리 | G37: data 추출 및 정리 (그래프 그리기, pore 크기별 비율 계산 등)
F38: 장비 세척 및 정리 | G38: 사용한 초자 세척 및 정리
C39: Tap 밀도 | F39: 샘플링 | G39: 메스실린더에 시료 40g 계량 후 투입 및 tap밀도 측정기에 장착
F40: 1000회 tapping | G40: 1000회 tapping
F41: Tap 밀도 측정 | G41: 메스실린더 부피 확인 및 tap 밀도 계산
F42: 장비 세척 및 정리 | G42: 사용한 메스실린더 세척 및 정리
...

Sheet 보조1-6_세부공정_분석_전해질
B3: LEVEL 0 | C3: LEVEL 1,2 | D3: LEVEL 2 | E3: LEVEL 3 | F3: LEVEL 4 | G3: LEVEL 5
B4: 실험 분류 | C4: 공정 | D4: 실험/분석법 상세 | E4: 실험 목적 | F4: Process step or SOP | G4: 상세 설명
C5: 전해질 제조 | F5: 원소재 물성을 고려 조성 선정 및 제조 | G5: 1. salt 및 첨가제 계량 2. 용매 첨가 후 교반 (salt가 용매에 용해되는 과정에서의 발열 주의) 3. 100% 용해된 전해질 저온 보관 고온에서 경시 우려가 있는 물질 첨가시 전해질 온도 낮춘 후 첨가 필요(소재특성을 고려한 투입순서 및 시점 고려 필요) | H5: 전해질 팀 특수 실험
C6: 전해질 HF 측정(상온) | F6: 적정용액 준비 | G6: 한 샘플 3회 정도 측정 (상온 수계, 적정용액 NaOH 0.01N) HF 측정 전 DOS 키를 눌러 tube에 있는 공기를 빼준다. STOP (FILL)을 눌러 vessel을 채워준다. | H6: 전해질 팀 특수 실험
F7: 증류수 준비 | G7: 100 mL 비커에 3차 증류수를 60mL 정도 채운다. | H7: 전해질 팀 특수 실험
F8: 교반 | G8: 2개의 probe를 담그고 stirring을 시작한다. (probe가 stirring bar에 닿지 않게 주의) | H8: 전해질 팀 특수 실험
F9: 샘플 정량화 | G9: 3 mL syringe에 1.0~1.5 mL의 샘플을 주입한다. | H9: 전해질 팀 특수 실험
F10: 샘플 정량화 | G10: 샘플 + syringe를 저울의 비커에 넣고 zero 해 준다. | H10: 전해질 팀 특수 실험
F11: 샘플 투입 | G11: 샘플을 비커에 주입한다. (샘플이 비커 벽에 묻지 않게 주의) | H11: 전해질 팀 특수 실험
F12: 측정 및 데이터 확보 | G12: Start를 누른다. “Sample size”가 화면에 나오면 빈 syringe를 저울의 비커에 넣고 측정되는 마이너스 값 (샘플의 무게)을 입력 후 Enter 키를 누른다.(데이터 확인) | H12: 전해질 팀 특수 실험
F13: 세정 | G13: Probe 세척: 아세톤으로 세척 후 3차 증류수로 세척(probe는 반드시 보관 액에 넣어 준다) 비커 세척: 아세톤으로 세척 후 60oC 오븐 보관 | H13: 전해질 팀 특수 실험
C14: 전해질 HF 측정(저온) | F14: 적정용액 준비 | G14: 한 샘플 3회 정도 측정 (저온 수계, 4 oC , 적정용액 NaOH 0.1N) HF 측정 전 DOS 키를 눌러 tube에 있는 공기를 빼준다. STOP (FILL)을 눌러 vessel을 채워준다. | H14: 전해질 팀 특수 실험
F15: 증류수 준비 | G15: 250 mL 비커에 3차 증류수를 100mL 정도 채운다. 이때 비커를 얼음 base에서 stirring하여 증류수 온도가 3~4℃가 될 수 있도록 한다. | H15: 전해질 팀 특수 실험
F16: 교반 | G16: 2개의 probe를 담그고 stirring을 시작한다. (probe가 stirring bar에 닿지 않게 주의) | H16: 전해질 팀 특수 실험
F17: 샘플 정량화 | G17: 15 - 20 mL의 샘플을 준비한다. | H17: 전해질 팀 특수 실험
F18: 샘플 정량화 | G18: 샘플 + bottle (혹은 syringe)를 저울의 비커에 넣고 zero 해 준다. | H18: 전해질 팀 특수 실험
F19: 샘플 투입 | G19: 샘플을 비커에 주입한다. (샘플이 비커 벽에 묻지 않게 주의) Start를 누른다. | H19: 전해질 팀 특수 실험
F20: 측정 및 데이터 확보 | G20: “Sample size”가 화면에 나오면 빈 bottle (혹은 syringe)를 저울의 비커에 넣고 측정되는 마이너스 값 (샘플의 무게)을 입력 후 Enter 키를 누른다. 적정이 완료되면 data가 자동으로 프린트 된다. | H20: 전해질 팀 특수 실험
F21: 세정 | G21: Probe 세척: 아세톤으로 세척 후 3차 증류수로 세척(probe는 반드시 보관 액에 넣어 준다.) 비커 세척: 아세톤으로 세척 후 60oC 오븐 보관 | H21: 전해질 팀 특수 실험
C22: 전해질 수분 함량 측정 | F22: 샘플 정량화 | G22: 한 샘플 3회 정도 측정 화면에 “ready”가 나와있으면 (or COND 지시 등이 안정되면) 수분 측정 가능. “ready”가 뜨지 않을 경우 담당자에게 문의. 1mL syringe에 0.7~1.0mL의 샘플을 주입한다. | H22: 전해질 팀 특수 실험
F23: 샙플 정량화 | G23: 샘플 + syringe를 저울의 비커에 넣고 zero 해 준다. | H23: 전해질 팀 특수 실험
F24: 적정준비 | G24: 화면에 “ready”가 나온 것을 (or COND 지시 등이 안정되면) 확인하고 Start 키를 누른다. (drift 값 5~7 수준 확인, Voltage 45mV수준 확인  Ready 조건). | H24: 전해질 팀 특수 실험
F25: 샘플투입 | G25: “Sample size”가 화면에 나오면 샘플을 주입한다. | H25: 전해질 팀 특수 실험
F26: 측정 | G26: 빈 syringe를 저울의 비커에 넣고 측정되는 마이너스 값 (샘플의 무게)을 입력 후 Enter 키를 누른다. 적정이 완료되면 화면에 나타난 값을 읽는다 | H26: 전해질 팀 특수 실험
C27: 전해질 이온 전도도 측정 | F27: 온도 setting | G27: Ionic conductivity meter와 표준용액을 setup 하고 장비 aging과 표준용액의 온도 평형을 위해 10분간 대기한다. | H27: 전해질 팀 특수 실험
F28: 표준소재 투입 | G28: 표준용액을 15ml Nalgene Bottle 하단 neck까지(15ml) 채운 후 Probe의 온도선 이상 잠기도록 Probe를 탐침한다. 팔콘 튜브(15ml)사용 시 전해액 4-5ml를 채워준다. | H28: 전해질 팀 특수 실험
F29: 표준소재 측정 조건 확보 | G29: 정확한 calibration을 위하여 표준용액의 온도가 25℃ 될 때까지 승온시키며 Display 창에서 아래의 표시가 나타날 수 있도록 승온시간을 충분히 주어준다.<Fig.1> (챔버안에 위치시킨 후 20min soaking시키고 이후 1min이상 측정값에 변화가 없을때를 온도평형시점으로 본다. | H29: 전해질 팀 특수 실험
F30: 표준소재 측정 및 확인 | G30: 4. 25℃가 되면 Calibration button을 누르고 곧이어 Read button을 눌러서 이온전도도 값이 12.88mS/cm가 나오도록 한다. 이때 사용하는 프로브의 전극셀상수(CC)가 spec과 일치하여 정상상태인지확인한다. | H30: 전해질 팀 특수 실험
F31: 표준 소재 세정 | G31: Probe는 Acetone을 이용하여 세척하고, blower를 이용하여 잔류 solvent를 모두 제거 후 Acetone의 완전한 기화 및 온도 회복을 위해 3~5분간 방치한다. | H31: 전해질 팀 특수 실험
F32: 측정 및 세정 | G32: 측정을 완료한 후에는 Water를 이용하여 Probe에 남아있는 salt를 완전히 제거하는 것이 바람직함. ※ Data의 편차가 발생하는 경우 표준 전해액을 이용하여 장비 신뢰성을 확인하는 것이 바람직함.  E2 전해액을(공장 생산품) 표준 전해액으로 선정하여 보관중. | H32: 전해질 팀 특수 실험
C33: 전해질 점도 측정 | F33: 점도계 세정 | G33: 점도계 호스에 연결된 DMC 담긴 주사기 피스톤 끝까지 눌러준 후 주사기 제거_x000B__x000B__x000B__x000B_ 25ml 주사기로 아세톤 20ml 주입_x000B_(주입 시 주사기 입구 호스에 돌려서 체결_x000B_ 10ml 주입 후 1~2ml 흡입, 다시 5ml 주입 후 1~2ml 흡입, 남은 아세톤 전부 주입)_x000B__x000B__x000B_ | H33: 전해질 팀 특수 실험
F34: 점도계 건조 | G34: 에어호스 연결 후 2분간 에어 주입으로 점도계 내부 건조 | H34: 전해질 팀 특수 실험
F35: 샘플 투입 및 측정 | G35: 6ml 주사기로 시료 5ml 담은 후 점도계 호스에 연결해 4ml 천천히 주입 (빠르게 주입 시 점도계 호스에 기포가 생길 경우 에러 발생하니 주의해서 주입) 시료 주입 후 Start 버튼 눌러서 측정 시작 | H35: 전해질 팀 특수 실험
F36: 재측정 | G36: 측정 완료 시 Lovis Dyn. Viscosity 값 확인 후 남은 시료 끝까지 주입 및 2번부터 다시 반복 | H36: 전해질 팀 특수 실험
F37: 점도계 세정 | G37: 모든 시료 측정 완료 시 아세톤으로 두번 세척 및 에어 주입 후 폐액통 비우기 | H37: 전해질 팀 특수 실험
F38: 보관액 충전 | G38: 6ml 주사기로 DMC (수분 제거 안 해도 됨) 5ml 담은 후 점도계 호스에 연결해 4ml 천천히 주입 (주사기는 꼽힌 상태로 그대로 두기) | H38: 전해질 팀 특수 실험
C39: 전해질 밀도 측정 | F39: 샘플 온도 측정 | G39: 한샘플 2회 이상 측정 밀도 측정 전 온도 안정화 목적으로 전해액을 상온에서 3시간 이상 방치 전해액 온도 측정 | H39: 전해질 팀 특수 실험
F40: 시료투입 | G40: PP Volumetric flask 입구쪽 벽면에 액체가 닿지 않게 전해액을 채운다. 메니스커스 현상을 감안하여 표면 가운데에 해당하는 위치의 눈금을 수평으로 보렴서 시료양을 맞춘다. | H40: 전해질 팀 특수 실험
F41: 측정 및 계산 | G41: 정확안 Volume으로 넣은 시료의 무게를 부피로 나누어 밀도를 계산한다. 밀도표기시 측정한 온도 기재한다. | H41: 전해질 팀 특수 실험
F42: 세정 | G42: 측정이 완료된 Volumetric flask는 증류수와 아세톤으로 세척하여 챔버에 보관한다. | H42: 전해질 팀 특수 실험
...

Sheet 보조1-7_세부공정_분석_분리막
B3: LEVEL 0 | C3: LEVEL 1,2 | D3: LEVEL 2 | E3: LEVEL 3 | F3: LEVEL 4 | G3: LEVEL 5
B4: 실험 분류 | C4: 공정 | D4: 실험/분석법 상세 | E4: 실험 목적 | F4: Process step or SOP | G4: 상세 설명
C5: SEM 분석 | F5: 샘플링 | G5: 샘플홀더에 카본테이브 부착 후, 소량의 powder (혹은 전극) 부착
F6: 샘플 홀더 장비로 투입 | G6: 샘플 홀더 장비로 투입
F7: 이미지 생성 | G7: 원하는 샘플 SEM 이미지 (입자의 형태를 잘 확인할 수 있는) 확인 후 배율별로 각각 캡쳐
F8: EDS 분석_x000D_ | G8: EDS 분석
F9: Data 저장_x000D_ | G9: Data 저장 후 추출
F10: 샘플 홀더 자동 배출_x000D_ | G10: 샘플 홀더 배출
F11: 샘플 홀더 클리닝_x000D_ | G11: 샘플 홀더 클리닝
C12: SEM 분석 (이온밀링) | F12: 이온밀링_x000D_ | G12: 일부 연구원들은 라이선스를 받아 직접 측정하기도 하나, quality있는 분석과 결과를 위해 분석담당에 분석 의뢰 중
F13: 전극 단면 분석 (SEM/EDS) | G13: 26년 기준 시료 ~20개 의뢰
C14: BET | F14: 샘플링 | G14: 비어있는 BET 초자의 무게 측정 -> 초자에 샘플 투입 (powder 0.2~2g/밀도가 낮은 샘플은 g수를 더 낮춰서 투입) -> 초자 neck부분에 묻어있는 시료는 면봉으로 닦아주기, 전처리 장비에 초자 연결
F15: 전처리_x000D_ | G15: 300℃ 진공상태에서 2시간동안 전처리 진행 (pore V.이 큰 원료의 경우, 전처리 시간 증가) --> 상온으로 식히기
F16: 무게 측정_x000D_ | G16: 전처리 진행한 샘플이 담긴 BET 초자의 무게 측정-> 샘플 무게 계산
F17: 측정 준비 | G17: BET 장비에 초자 장착 -> 가스보관실에서 액체 질소 소분 후 장비 용기에 덜어주기, 측정 패턴/파일명 등 설정
F18: 측정 | G18: 측정 시작 (장비에 따라 2개 소재 동시 분석 가능)
F19: Data 정리 | G19: data 추출 및 정리 (그래프 그리기, pore 크기별 비율 계산 등)
F20: 장비 세척 및 정리 | G20: 사용한 초자 세척 및 정리
C21: 분리막 팀 특수 실험
C22: 분리막 두께 측정_x000D_ | F22: 분리막 타발 | G22: 분리막 5 x 5 cm 타발한다. | H22: 분리막 팀 특수 실험
F23: 분리막 두께 측정 | G23: 분리막의 상/하/좌/우/중앙 5 point 두께 측정한다. | H23: 분리막 팀 특수 실험
C24: 분리막 무게 측정_x000D_ | F24: 분리막 타발 | G24: 분리막 5 x 5 cm 타발한다. | H24: 분리막 팀 특수 실험
F25: 분리막 무게 측정 | G25: 분리막의 무게를 측정한다. | H25: 분리막 팀 특수 실험
C26: 분리막 통기성 측정_x000D_ | F26: 분리막 타발 | G26: 분리막 5 x 5 cm 타발한다. | H26: 분리막 팀 특수 실험
F27: 분리막 통기도 측정 | G27: 분리막의 통기도 측정한다. | H27: 분리막 팀 특수 실험
C28: Puncture stress_x000D_ | F28: 분리막 타발 후, 장비에 분리막 고정 | G28: 5cm x 5cm 로 타발 된 분리막을 고정한다. | H28: 분리막 팀 특수 실험
F29: Needle의 위치를 분리막에 맞닿게 위치 조절 | G29: Needle의 위치를 분리막에 맞닿게 위치 조절한다. | H29: 분리막 팀 특수 실험
F30: 천공 강도 측정 프로그램을 실행 | G30: Nexygen 실행 후 천공 테스트 선택 -> 파일명 설정의 순서로 진행 후 샘플명 입력 후 시작한다. | H30: 분리막 팀 특수 실험
F31: Data 분석 및 추출 | G31: 데이터를 취득한다. | H31: 분리막 팀 특수 실험
C32: Tensile strength (인장강도)_x000D_ | F32: 분리막 타발 | G32: 분리막을 15 mm x 200 mm로 MD/TD 방향 구분하여 6ea 샘플 준비한다 | H32: 분리막 팀 특수 실험
F33: 장비에 분리막 고정 | G33: 타발된 분리막을 인장 강도 Jig에 100 mm로 고정한다. | H33: 분리막 팀 특수 실험
F34: 인장 강도 측정 프로그램 실행 | G34: 인장 강도 테스트 선택 -> 파일명 설정의 순서로 진행 후 샘플명 입력 후 시작한다. | H34: 분리막 팀 특수 실험
F35: Data 분석 및 추출 | G35: 데이터를 취득한다. | H35: 분리막 팀 특수 실험
C36: Dry 열수축 테스트 | F36: 분리막 타발하여 준비 | G36: 분리막을 5 x 5 cm 타발한다. | H36: 분리막 팀 특수 실험
F37: 오븐내에 분리막 가열 진행 | G37: 오븐에 A4 11장 x 11장 스택 사이에 분리막을 넣은 후 30분간 가열 | H37: 분리막 팀 특수 실험
F38: 수축된 분리막 길이 측정 | G38: 분리막 길이 변화를 MD/TD 방향으로 측정한다. | H38: 분리막 팀 특수 실험
C39: Wet 열수축 테스트 | F39: 분리막 타발하여 준비 | G39: 분리막을 5x5cm 로 타발한다. | H39: 분리막 팀 특수 실험
F40: Al pouch에 분리막을 넣고, 전해액 넣은 후 밀봉 | G40: Al pouch에 분리막을 넣은 후, 전해액을 1g 넣고 밀봉한다 | H40: 분리막 팀 특수 실험
F41: 30분간 분리막을 가열 | G41: 오븐에 30분 간 방치한다. | H41: 분리막 팀 특수 실험
F42: 수축된 분리막 길이 측정 | G42: 분리막 길이 변화를 MD/TD 방향으로 측정한다. | H42: 분리막 팀 특수 실험
...

Sheet 보조2-1_세부공정_실험_양극재
B3: LEVEL 0 | C3: LEVEL 1,2 | D3: LEVEL 2 | E3: LEVEL 3 | F3: LEVEL 4 | G3: LEVEL 5
B4: 실험 분류 | C4: 공정 | D4: 실험/분석법 상세 | E4: 실험 목적 | F4: Process step or SOP | G4: 상세 설명
C5: 슬러리 제작 | D5: 양극 슬러리 제작 | F5: 1차 재료 계량 | G5: 도전재+바인더 premixing 계량 (slurry 제작 전 믹서 사용하여 미리 대량 제조). 손실 방지위해 mixing통 (Nalgene bottle)에 직접 계량
F6: 2차 계량 | G6: 활물질 계량 (유선지 대신 Al foil 이용) 뒤 mixing통에 혼합 (슬러리 조성은 평가 양극재마다 상이)
F7: 고형분 맞추기 | G7: 고형분 양 고려하여 NMP 추가 투입
F8: 1차 믹싱 | G8: 슬러리 1차 혼합 (thinky mixer) (믹싱 rpm 및 시간은 평가 양극재마다 상이)
F9: 뭉친부분 풀어주기 | G9: Nalgene bottle 개봉 뒤 spatula로 휘저으며 뭉친 부분 풀어주기
F10: 2차 믹싱 | G10: 슬러리 2차 혼합 (thinky mixer)
F11: 장비 세척 및 정리 | G11: 믹싱 완료 후 장비 세척 및 정리
C12: 전극 제작 | D12: 양극 전극 제작 | F12: 소재준비 (이송) | G12: 양극 슬러리 준비
F13: 코팅 | G13: 슬러리를 Al foil 위에 도포한 후, 목표 전극무게 (~420mg/25cm2) 수준이 되도록 doctor blade gap 조절하여 코팅
F14: 건조 | G14: 코팅된 Al foil이 들뜨거나 기울어져 슬러리 로딩 불균일이 발생하지 않도록 건조과정 동안 고정 필요
F15: 장비 세척 및 정리 | G15: 사용한 코터 세척 및 정리
F16: 압연 | G16: 2cm 폭으로 전극 cutting 뒤 target porosity에 맞게 압연기 gap 조절하여 압연 2회 진행 (lab설비 기준)
F17: 장비 세척 및 정리 | G17: 사용한 압연기 세척 및 정리
C18: 셀 제작_코인셀 | D18: 코인셀 조립 | F18: 코인셀용 양극 타발 | G18: 코인셀용 양/음극 타발 (1소재당 코인셀 4~5개 제조)
F19: 무게 측정/기록 | G19: 타발된 전극 무게 측정 (target 무게에 젤 적합한 전극 사용), Cu foil 무게 측정
F20: 두께 측정/기록 | G20: 타발된 전극 두께 측정 (target 두께에 젤 적합한 전극 사용), Cu foil 두께 측정
F21: Li metal 타발 | G21: 글러브박스 내에 있는 Li metal 소분 -> 드라이룸으로 이동 후 타발+Ni mesh 부착
F22: 분리막 타발 | G22: 분리막타발
F23: 부품 준비 | G23: 제작할 코인셀 개수에 맞춰 코인셀용 부품 준비
F24: 코인셀 조립_x000D_ | G24: 코인셀 조립 및 클램핑, 에틸알콜로 누액된 전해액 닦기 등
F25: 코인셀 조립 후 OCV 측정_x000D_ | G25: OCV 측정
D26: 셀평가 | F26: 비어있는 충방전 채널에 코인셀 체결 | G26: 전극 로딩을 반영하여, 0.1/0.005C에 해당하는 current 값 확인, 충방전기 챔버로 이동 후 , 코인셀 체결, 충방전 패턴 설정 및 저장
F27: 충방전 평가 진행 | G27: 30시간 상온 wetting 후, 충방전 평가 진행
F28: Data 정리 및 용량/효율 계산_x000D_ | G28: data추출 및 정리
F29: 그래프 생성 _x000D_ | G29: 오리진 프로그램으로 그래프 생성
F30: 비어있는 충방전 채널에 코인셀 체결_x000D_ | G30: 전극 로딩 반영, C-rate에 해당하는 current값 확인, 충방전기 챔버로 이동 후 , 코인셀 체결, 충방전 패턴 설정 및 저장
F31: Rate 별 평가 | G31: rate 별 충/방전 평가 진행
F32: Data 정리_x000D_ | G32: data추출 및 정리
F33: 그래프 생성_x000D_ | G33: 오리진 프로그램으로 그래프 생성
C34: 셀 제작_모노셀 | D34: 소재 준비 | F34: 모노셀 용 전극 타발 | G34: 양/음극 모노셀 타발
F35: 양/음극 tap 닦기 | G35: tap 부분의 활물질 층 제거
F36: 전극 V/D 챔버로 이동 | G36: Al foil로 감싼 후 드라이룸 내의 V/D 챔버로 이동
F37: 전극 건조 | G37: V/D 챔버에서 130℃ 진공상태에서 8시간동안 전극 건조
D38: 모노셀 조립 | F38: 실링 후, 모노셀 수작업실 전달 | G38: 실링 후, 모노셀 수작업실 (전지동)에 전달
F39: 모노셀 조립 | G39: 모노셀 조립
F40: 수작업실에서 모노셀 수령 | G40: 모노셀 수작업실(전지동)에서 모노셀 수령 후 건조 오븐에 투입
F41: 모노셀 건조 | G41: 55~60℃ 챔버에서 1~2일 이상 건조
D42: 전해액 주액 | F42: 건조된 모노셀 실링 후, degas 장비로 이동 | G42: 건조된 모노셀 실링/ 전해액, 피펫 등 준비 후 degas 장비로 이동 (드라이룸)
...

Sheet 보조2-2_세부공정_실험_리사이클
B3: LEVEL 0 | C3: LEVEL 1,2 | D3: LEVEL 2 | E3: LEVEL 3 | F3: LEVEL 4 | G3: LEVEL 5
B4: 실험 분류 | C4: 공정 | D4: 실험/분석법 상세 | E4: 실험 목적 | F4: Process step or SOP | G4: 상세 설명
C5: 슬러리 제작 | D5: 양극 슬러리 제작 | F5: 1차 재료 계량 | G5: 도전재+바인더 premixing 계량 (slurry 제작 전 믹서 사용하여 미리 대량 제조). 손실 방지위해 mixing통 (Nalgene bottle)에 직접 계량
F6: 2차 계량 | G6: 활물질 계량 (유선지 대신 Al foil 이용) 뒤 mixing통에 혼합 (슬러리 조성은 평가 양극재마다 상이)
F7: 고형분 맞추기 | G7: 고형분 양 고려하여 NMP 추가 투입
F8: 1차 믹싱 | G8: 슬러리 1차 혼합 (thinky mixer) (믹싱 rpm 및 시간은 평가 양극재마다 상이)
F9: 뭉친부분 풀어주기 | G9: Nalgene bottle 개봉 뒤 spatula로 휘저으며 뭉친 부분 풀어주기
F10: 2차 믹싱 | G10: 슬러리 2차 혼합 (thinky mixer)
F11: 장비 세척 및 정리 | G11: 믹싱 완료 후 장비 세척 및 정리
C12: 전극 제작 | D12: 양극 전극 제작 | F12: 소재준비 (이송) | G12: 양극 슬러리 준비
F13: 코팅 | G13: 슬러리를 Al foil 위에 도포한 후, 목표 전극무게 (~420mg/25cm2) 수준이 되도록 doctor blade gap 조절하여 코팅
F14: 건조 | G14: 코팅된 Al foil이 들뜨거나 기울어져 슬러리 로딩 불균일이 발생하지 않도록 건조과정 동안 고정 필요
F15: 장비 세척 및 정리 | G15: 사용한 코터 세척 및 정리
F16: 압연 | G16: 2cm 폭으로 전극 cutting 뒤 target porosity에 맞게 압연기 gap 조절하여 압연 2회 진행 (lab설비 기준)
F17: 장비 세척 및 정리 | G17: 사용한 압연기 세척 및 정리
C18: 셀 제작_코인셀 | D18: 코인셀 조립 | F18: 코인셀 조립 | G18: 코인셀 조립 및 클램핑, 에틸알콜로 누액된 전해액 닦기 등
F19: 코인셀 조립 후 OCV 측정 | G19: OCV 측정
D20: 셀평가 | F20: 비어있는 충방전 채널에 코인셀 체결 | G20: 전극 로딩을 반영하여, 0.1/0.005C에 해당하는 current 값 확인, 충방전기 챔버로 이동 후 , 코인셀 체결, 충방전 패턴 설정 및 저장
F21: 충방전 평가 진행 | G21: 30시간 상온 wetting 후, 충방전 평가 진행
F22: Data 정리 및 용량/효율 계산 | G22: data추출 및 정리
F23: 그래프 생성 | G23: 오리진 프로그램으로 그래프 생성
F24: 비어있는 충방전 채널에 코인셀 체결 | G24: 전극 로딩 반영, C-rate에 해당하는 current값 확인, 충방전기 챔버로 이동 후 , 코인셀 체결, 충방전 패턴 설정 및 저장
F25: Rate 별 평가 | G25: rate 별 충/방전 평가 진행
F26: Data 정리 | G26: data추출 및 정리
F27: 그래프 생성 | G27: 오리진 프로그램으로 그래프 생성
C28: 셀 제작_모노셀 | D28: 소재 준비 | F28: 모노셀 용 전극 타발 | G28: 양/음극 모노셀 타발
D29: 소재 준비 | F29: 양/음극 tap 닦기 | G29: tap 부분의 활물질 층 제거
D30: 모노셀 조립 | F30: 실링 후, 모노셀 수작업실 전달 | G30: 실링 후, 모노셀 수작업실 (전지동)에 전달
D31: 모노셀 조립 | F31: 모노셀 조립 | G31: 모노셀 조립
D32: 모노셀 조립 | F32: 수작업실에서 모노셀 수령 | G32: 모노셀 수작업실(전지동)에서 모노셀 수령
D33: 전해액 주액 | F33: 건조된 모노셀 실링 후, degas 장비로 이동 | G33: 건조된 모노셀 실링/ 전해액, 피펫 등 준비 후 degas 장비로 이동 (드라이룸)
D34: 전해액 주액 | F34: 전해액 주액 | G34: 건조된 모노셀에 전해액 주액
D35: wetting | F35: 전해액 wetting | G35: 진공챔버에서 10초씩 3번 vacuum 시행
D36: 실링 | F36: 모노셀 실링 | G36: degas 장비에서 모노셀 실링(진공압착), 수기로 cell number 기입
D37: 활성화 | F37: 비어있는 충방전 채널에 모노셀 체결 | G37: 충방전기 챔버로 이동 후 , 모노셀 체결
D38: 활성화 | F38: 모노셀의 활성화 공정 | G38: 10시간 상온 wetting 후, SOC 30% 충전 활성화 공정 진행
D39: degas | F39: 활성화 완료된 모노셀, degas 장비로 이동 | G39: 활성화 완료된 모노셀에 포스트잇 부착 +degas 장비(드라이룸)으로 이동
D40: degas | F40: 모노셀 부분 6-7cm로 맞추어 cutting | G40: 모노셀 부분 6cm로 맞추어 cutting
... D51: 셀평가 | F51: Data 정리 | G51: data 추출 및 정리, 그래프 그리기 등 (수명, 저장 수시 정리 필요)

